2022-01-12 11:13:45,132 INFO     Started server process [17596]
2022-01-12 11:13:45,132 INFO     Waiting for application startup.
2022-01-12 11:13:45,139 INFO     Application startup complete.
2022-01-12 11:13:53,314 INFO     Opened weight page
2022-01-12 11:13:58,645 INFO     Opened head circumference page
2022-01-12 11:13:58,673 ERROR    Exception in ASGI application
Traceback (most recent call last):
  File "C:\Users\PatCa\anaconda3\lib\site-packages\fastapi\encoders.py", line 137, in jsonable_encoder
    data = dict(obj)
TypeError: 'numpy.int64' object is not iterable

During handling of the above exception, another exception occurred:

Traceback (most recent call last):
  File "C:\Users\PatCa\anaconda3\lib\site-packages\fastapi\encoders.py", line 141, in jsonable_encoder
    data = vars(obj)
TypeError: vars() argument must have __dict__ attribute

During handling of the above exception, another exception occurred:

Traceback (most recent call last):
  File "C:\Users\PatCa\anaconda3\lib\site-packages\uvicorn\protocols\http\h11_impl.py", line 373, in run_asgi
    result = await app(self.scope, self.receive, self.send)
  File "C:\Users\PatCa\anaconda3\lib\site-packages\uvicorn\middleware\proxy_headers.py", line 75, in __call__
    return await self.app(scope, receive, send)
  File "C:\Users\PatCa\anaconda3\lib\site-packages\fastapi\applications.py", line 208, in __call__
    await super().__call__(scope, receive, send)
  File "C:\Users\PatCa\anaconda3\lib\site-packages\starlette\applications.py", line 112, in __call__
    await self.middleware_stack(scope, receive, send)
  File "C:\Users\PatCa\anaconda3\lib\site-packages\starlette\middleware\errors.py", line 181, in __call__
    raise exc
  File "C:\Users\PatCa\anaconda3\lib\site-packages\starlette\middleware\errors.py", line 159, in __call__
    await self.app(scope, receive, _send)
  File "C:\Users\PatCa\anaconda3\lib\site-packages\starlette\exceptions.py", line 82, in __call__
    raise exc
  File "C:\Users\PatCa\anaconda3\lib\site-packages\starlette\exceptions.py", line 71, in __call__
    await self.app(scope, receive, sender)
  File "C:\Users\PatCa\anaconda3\lib\site-packages\starlette\routing.py", line 656, in __call__
    await route.handle(scope, receive, send)
  File "C:\Users\PatCa\anaconda3\lib\site-packages\starlette\routing.py", line 259, in handle
    await self.app(scope, receive, send)
  File "C:\Users\PatCa\anaconda3\lib\site-packages\starlette\routing.py", line 61, in app
    response = await func(request)
  File "C:\Users\PatCa\anaconda3\lib\site-packages\fastapi\routing.py", line 234, in app
    response_data = await serialize_response(
  File "C:\Users\PatCa\anaconda3\lib\site-packages\fastapi\routing.py", line 148, in serialize_response
    return jsonable_encoder(response_content)
  File "C:\Users\PatCa\anaconda3\lib\site-packages\fastapi\encoders.py", line 93, in jsonable_encoder
    encoded_value = jsonable_encoder(
  File "C:\Users\PatCa\anaconda3\lib\site-packages\fastapi\encoders.py", line 145, in jsonable_encoder
    return jsonable_encoder(
  File "C:\Users\PatCa\anaconda3\lib\site-packages\fastapi\encoders.py", line 93, in jsonable_encoder
    encoded_value = jsonable_encoder(
  File "C:\Users\PatCa\anaconda3\lib\site-packages\fastapi\encoders.py", line 144, in jsonable_encoder
    raise ValueError(errors)
ValueError: [TypeError("'numpy.int64' object is not iterable"), TypeError('vars() argument must have __dict__ attribute')]
2022-01-12 11:13:58,715 INFO     Opened favicon
2022-01-12 11:13:59,021 ERROR    Exception in ASGI application
Traceback (most recent call last):
  File "C:\Users\PatCa\anaconda3\lib\site-packages\starlette\responses.py", line 282, in __call__
    stat_result = await anyio.to_thread.run_sync(os.stat, self.path)
  File "C:\Users\PatCa\anaconda3\lib\site-packages\anyio\to_thread.py", line 28, in run_sync
    return await get_asynclib().run_sync_in_worker_thread(func, *args, cancellable=cancellable,
  File "C:\Users\PatCa\anaconda3\lib\site-packages\anyio\_backends\_asyncio.py", line 805, in run_sync_in_worker_thread
    return await future
  File "C:\Users\PatCa\anaconda3\lib\site-packages\anyio\_backends\_asyncio.py", line 743, in run
    result = func(*args)
FileNotFoundError: [WinError 2] The system cannot find the file specified: 'favicon.ico'

During handling of the above exception, another exception occurred:

Traceback (most recent call last):
  File "C:\Users\PatCa\anaconda3\lib\site-packages\uvicorn\protocols\http\h11_impl.py", line 373, in run_asgi
    result = await app(self.scope, self.receive, self.send)
  File "C:\Users\PatCa\anaconda3\lib\site-packages\uvicorn\middleware\proxy_headers.py", line 75, in __call__
    return await self.app(scope, receive, send)
  File "C:\Users\PatCa\anaconda3\lib\site-packages\fastapi\applications.py", line 208, in __call__
    await super().__call__(scope, receive, send)
  File "C:\Users\PatCa\anaconda3\lib\site-packages\starlette\applications.py", line 112, in __call__
    await self.middleware_stack(scope, receive, send)
  File "C:\Users\PatCa\anaconda3\lib\site-packages\starlette\middleware\errors.py", line 181, in __call__
    raise exc
  File "C:\Users\PatCa\anaconda3\lib\site-packages\starlette\middleware\errors.py", line 159, in __call__
    await self.app(scope, receive, _send)
  File "C:\Users\PatCa\anaconda3\lib\site-packages\starlette\exceptions.py", line 82, in __call__
    raise exc
  File "C:\Users\PatCa\anaconda3\lib\site-packages\starlette\exceptions.py", line 71, in __call__
    await self.app(scope, receive, sender)
  File "C:\Users\PatCa\anaconda3\lib\site-packages\starlette\routing.py", line 656, in __call__
    await route.handle(scope, receive, send)
  File "C:\Users\PatCa\anaconda3\lib\site-packages\starlette\routing.py", line 259, in handle
    await self.app(scope, receive, send)
  File "C:\Users\PatCa\anaconda3\lib\site-packages\starlette\routing.py", line 64, in app
    await response(scope, receive, send)
  File "C:\Users\PatCa\anaconda3\lib\site-packages\starlette\responses.py", line 285, in __call__
    raise RuntimeError(f"File at path {self.path} does not exist.")
RuntimeError: File at path favicon.ico does not exist.
2022-01-12 11:15:16,850 INFO     Started server process [6820]
2022-01-12 11:15:16,850 INFO     Waiting for application startup.
2022-01-12 11:15:16,852 INFO     Application startup complete.
2022-01-12 11:15:19,327 INFO     Started server process [21172]
2022-01-12 11:15:19,328 INFO     Waiting for application startup.
2022-01-12 11:15:19,329 INFO     Application startup complete.
2022-01-12 11:15:22,189 INFO     Opened head circumference page
2022-01-12 11:15:22,257 ERROR    Exception in ASGI application
Traceback (most recent call last):
  File "C:\Users\PatCa\anaconda3\lib\site-packages\fastapi\encoders.py", line 137, in jsonable_encoder
    data = dict(obj)
TypeError: 'numpy.int64' object is not iterable

During handling of the above exception, another exception occurred:

Traceback (most recent call last):
  File "C:\Users\PatCa\anaconda3\lib\site-packages\fastapi\encoders.py", line 141, in jsonable_encoder
    data = vars(obj)
TypeError: vars() argument must have __dict__ attribute

During handling of the above exception, another exception occurred:

Traceback (most recent call last):
  File "C:\Users\PatCa\anaconda3\lib\site-packages\uvicorn\protocols\http\h11_impl.py", line 373, in run_asgi
    result = await app(self.scope, self.receive, self.send)
  File "C:\Users\PatCa\anaconda3\lib\site-packages\uvicorn\middleware\proxy_headers.py", line 75, in __call__
    return await self.app(scope, receive, send)
  File "C:\Users\PatCa\anaconda3\lib\site-packages\fastapi\applications.py", line 208, in __call__
    await super().__call__(scope, receive, send)
  File "C:\Users\PatCa\anaconda3\lib\site-packages\starlette\applications.py", line 112, in __call__
    await self.middleware_stack(scope, receive, send)
  File "C:\Users\PatCa\anaconda3\lib\site-packages\starlette\middleware\errors.py", line 181, in __call__
    raise exc
  File "C:\Users\PatCa\anaconda3\lib\site-packages\starlette\middleware\errors.py", line 159, in __call__
    await self.app(scope, receive, _send)
  File "C:\Users\PatCa\anaconda3\lib\site-packages\starlette\exceptions.py", line 82, in __call__
    raise exc
  File "C:\Users\PatCa\anaconda3\lib\site-packages\starlette\exceptions.py", line 71, in __call__
    await self.app(scope, receive, sender)
  File "C:\Users\PatCa\anaconda3\lib\site-packages\starlette\routing.py", line 656, in __call__
    await route.handle(scope, receive, send)
  File "C:\Users\PatCa\anaconda3\lib\site-packages\starlette\routing.py", line 259, in handle
    await self.app(scope, receive, send)
  File "C:\Users\PatCa\anaconda3\lib\site-packages\starlette\routing.py", line 61, in app
    response = await func(request)
  File "C:\Users\PatCa\anaconda3\lib\site-packages\fastapi\routing.py", line 234, in app
    response_data = await serialize_response(
  File "C:\Users\PatCa\anaconda3\lib\site-packages\fastapi\routing.py", line 148, in serialize_response
    return jsonable_encoder(response_content)
  File "C:\Users\PatCa\anaconda3\lib\site-packages\fastapi\encoders.py", line 93, in jsonable_encoder
    encoded_value = jsonable_encoder(
  File "C:\Users\PatCa\anaconda3\lib\site-packages\fastapi\encoders.py", line 145, in jsonable_encoder
    return jsonable_encoder(
  File "C:\Users\PatCa\anaconda3\lib\site-packages\fastapi\encoders.py", line 93, in jsonable_encoder
    encoded_value = jsonable_encoder(
  File "C:\Users\PatCa\anaconda3\lib\site-packages\fastapi\encoders.py", line 144, in jsonable_encoder
    raise ValueError(errors)
ValueError: [TypeError("'numpy.int64' object is not iterable"), TypeError('vars() argument must have __dict__ attribute')]
2022-01-12 11:15:58,772 INFO     Started server process [10560]
2022-01-12 11:15:58,772 INFO     Waiting for application startup.
2022-01-12 11:15:58,773 INFO     Application startup complete.
2022-01-12 11:17:06,919 INFO     Opened weight page
2022-01-12 11:17:42,161 INFO     Started server process [16540]
2022-01-12 11:17:42,161 INFO     Waiting for application startup.
2022-01-12 11:17:42,161 INFO     Application startup complete.
2022-01-12 11:17:47,912 INFO     Opened height page
2022-01-12 11:17:47,968 ERROR    Exception in ASGI application
Traceback (most recent call last):
  File "C:\Users\PatCa\anaconda3\lib\site-packages\fastapi\encoders.py", line 137, in jsonable_encoder
    data = dict(obj)
TypeError: 'numpy.int64' object is not iterable

During handling of the above exception, another exception occurred:

Traceback (most recent call last):
  File "C:\Users\PatCa\anaconda3\lib\site-packages\fastapi\encoders.py", line 141, in jsonable_encoder
    data = vars(obj)
TypeError: vars() argument must have __dict__ attribute

During handling of the above exception, another exception occurred:

Traceback (most recent call last):
  File "C:\Users\PatCa\anaconda3\lib\site-packages\uvicorn\protocols\http\h11_impl.py", line 373, in run_asgi
    result = await app(self.scope, self.receive, self.send)
  File "C:\Users\PatCa\anaconda3\lib\site-packages\uvicorn\middleware\proxy_headers.py", line 75, in __call__
    return await self.app(scope, receive, send)
  File "C:\Users\PatCa\anaconda3\lib\site-packages\fastapi\applications.py", line 208, in __call__
    await super().__call__(scope, receive, send)
  File "C:\Users\PatCa\anaconda3\lib\site-packages\starlette\applications.py", line 112, in __call__
    await self.middleware_stack(scope, receive, send)
  File "C:\Users\PatCa\anaconda3\lib\site-packages\starlette\middleware\errors.py", line 181, in __call__
    raise exc
  File "C:\Users\PatCa\anaconda3\lib\site-packages\starlette\middleware\errors.py", line 159, in __call__
    await self.app(scope, receive, _send)
  File "C:\Users\PatCa\anaconda3\lib\site-packages\starlette\exceptions.py", line 82, in __call__
    raise exc
  File "C:\Users\PatCa\anaconda3\lib\site-packages\starlette\exceptions.py", line 71, in __call__
    await self.app(scope, receive, sender)
  File "C:\Users\PatCa\anaconda3\lib\site-packages\starlette\routing.py", line 656, in __call__
    await route.handle(scope, receive, send)
  File "C:\Users\PatCa\anaconda3\lib\site-packages\starlette\routing.py", line 259, in handle
    await self.app(scope, receive, send)
  File "C:\Users\PatCa\anaconda3\lib\site-packages\starlette\routing.py", line 61, in app
    response = await func(request)
  File "C:\Users\PatCa\anaconda3\lib\site-packages\fastapi\routing.py", line 234, in app
    response_data = await serialize_response(
  File "C:\Users\PatCa\anaconda3\lib\site-packages\fastapi\routing.py", line 148, in serialize_response
    return jsonable_encoder(response_content)
  File "C:\Users\PatCa\anaconda3\lib\site-packages\fastapi\encoders.py", line 145, in jsonable_encoder
    return jsonable_encoder(
  File "C:\Users\PatCa\anaconda3\lib\site-packages\fastapi\encoders.py", line 93, in jsonable_encoder
    encoded_value = jsonable_encoder(
  File "C:\Users\PatCa\anaconda3\lib\site-packages\fastapi\encoders.py", line 145, in jsonable_encoder
    return jsonable_encoder(
  File "C:\Users\PatCa\anaconda3\lib\site-packages\fastapi\encoders.py", line 93, in jsonable_encoder
    encoded_value = jsonable_encoder(
  File "C:\Users\PatCa\anaconda3\lib\site-packages\fastapi\encoders.py", line 144, in jsonable_encoder
    raise ValueError(errors)
ValueError: [TypeError("'numpy.int64' object is not iterable"), TypeError('vars() argument must have __dict__ attribute')]
2022-01-12 11:18:34,361 INFO     Started server process [6700]
2022-01-12 11:18:34,361 INFO     Waiting for application startup.
2022-01-12 11:18:34,365 INFO     Application startup complete.
2022-01-12 11:18:36,825 INFO     Started server process [18784]
2022-01-12 11:18:36,826 INFO     Waiting for application startup.
2022-01-12 11:18:36,826 INFO     Application startup complete.
2022-01-12 11:18:39,580 INFO     Opened height page
2022-01-12 11:18:39,638 ERROR    Exception in ASGI application
Traceback (most recent call last):
  File "C:\Users\PatCa\anaconda3\lib\site-packages\fastapi\encoders.py", line 137, in jsonable_encoder
    data = dict(obj)
TypeError: 'numpy.int64' object is not iterable

During handling of the above exception, another exception occurred:

Traceback (most recent call last):
  File "C:\Users\PatCa\anaconda3\lib\site-packages\fastapi\encoders.py", line 141, in jsonable_encoder
    data = vars(obj)
TypeError: vars() argument must have __dict__ attribute

During handling of the above exception, another exception occurred:

Traceback (most recent call last):
  File "C:\Users\PatCa\anaconda3\lib\site-packages\uvicorn\protocols\http\h11_impl.py", line 373, in run_asgi
    result = await app(self.scope, self.receive, self.send)
  File "C:\Users\PatCa\anaconda3\lib\site-packages\uvicorn\middleware\proxy_headers.py", line 75, in __call__
    return await self.app(scope, receive, send)
  File "C:\Users\PatCa\anaconda3\lib\site-packages\fastapi\applications.py", line 208, in __call__
    await super().__call__(scope, receive, send)
  File "C:\Users\PatCa\anaconda3\lib\site-packages\starlette\applications.py", line 112, in __call__
    await self.middleware_stack(scope, receive, send)
  File "C:\Users\PatCa\anaconda3\lib\site-packages\starlette\middleware\errors.py", line 181, in __call__
    raise exc
  File "C:\Users\PatCa\anaconda3\lib\site-packages\starlette\middleware\errors.py", line 159, in __call__
    await self.app(scope, receive, _send)
  File "C:\Users\PatCa\anaconda3\lib\site-packages\starlette\exceptions.py", line 82, in __call__
    raise exc
  File "C:\Users\PatCa\anaconda3\lib\site-packages\starlette\exceptions.py", line 71, in __call__
    await self.app(scope, receive, sender)
  File "C:\Users\PatCa\anaconda3\lib\site-packages\starlette\routing.py", line 656, in __call__
    await route.handle(scope, receive, send)
  File "C:\Users\PatCa\anaconda3\lib\site-packages\starlette\routing.py", line 259, in handle
    await self.app(scope, receive, send)
  File "C:\Users\PatCa\anaconda3\lib\site-packages\starlette\routing.py", line 61, in app
    response = await func(request)
  File "C:\Users\PatCa\anaconda3\lib\site-packages\fastapi\routing.py", line 234, in app
    response_data = await serialize_response(
  File "C:\Users\PatCa\anaconda3\lib\site-packages\fastapi\routing.py", line 148, in serialize_response
    return jsonable_encoder(response_content)
  File "C:\Users\PatCa\anaconda3\lib\site-packages\fastapi\encoders.py", line 93, in jsonable_encoder
    encoded_value = jsonable_encoder(
  File "C:\Users\PatCa\anaconda3\lib\site-packages\fastapi\encoders.py", line 145, in jsonable_encoder
    return jsonable_encoder(
  File "C:\Users\PatCa\anaconda3\lib\site-packages\fastapi\encoders.py", line 93, in jsonable_encoder
    encoded_value = jsonable_encoder(
  File "C:\Users\PatCa\anaconda3\lib\site-packages\fastapi\encoders.py", line 144, in jsonable_encoder
    raise ValueError(errors)
ValueError: [TypeError("'numpy.int64' object is not iterable"), TypeError('vars() argument must have __dict__ attribute')]
2022-01-12 11:19:21,761 INFO     Started server process [18300]
2022-01-12 11:19:21,762 INFO     Waiting for application startup.
2022-01-12 11:19:21,762 INFO     Application startup complete.
2022-01-12 11:19:24,445 INFO     Started server process [16128]
2022-01-12 11:19:24,445 INFO     Waiting for application startup.
2022-01-12 11:19:24,449 INFO     Application startup complete.
2022-01-12 11:19:34,083 INFO     Opened weight page
2022-01-12 11:20:07,214 INFO     Started server process [15440]
2022-01-12 11:20:07,214 INFO     Waiting for application startup.
2022-01-12 11:20:07,216 INFO     Application startup complete.
2022-01-12 11:20:14,310 INFO     Opened head circumference page
2022-01-12 11:20:14,364 ERROR    Exception in ASGI application
Traceback (most recent call last):
  File "C:\Users\PatCa\anaconda3\lib\site-packages\fastapi\encoders.py", line 137, in jsonable_encoder
    data = dict(obj)
TypeError: 'numpy.int64' object is not iterable

During handling of the above exception, another exception occurred:

Traceback (most recent call last):
  File "C:\Users\PatCa\anaconda3\lib\site-packages\fastapi\encoders.py", line 141, in jsonable_encoder
    data = vars(obj)
TypeError: vars() argument must have __dict__ attribute

During handling of the above exception, another exception occurred:

Traceback (most recent call last):
  File "C:\Users\PatCa\anaconda3\lib\site-packages\uvicorn\protocols\http\h11_impl.py", line 373, in run_asgi
    result = await app(self.scope, self.receive, self.send)
  File "C:\Users\PatCa\anaconda3\lib\site-packages\uvicorn\middleware\proxy_headers.py", line 75, in __call__
    return await self.app(scope, receive, send)
  File "C:\Users\PatCa\anaconda3\lib\site-packages\fastapi\applications.py", line 208, in __call__
    await super().__call__(scope, receive, send)
  File "C:\Users\PatCa\anaconda3\lib\site-packages\starlette\applications.py", line 112, in __call__
    await self.middleware_stack(scope, receive, send)
  File "C:\Users\PatCa\anaconda3\lib\site-packages\starlette\middleware\errors.py", line 181, in __call__
    raise exc
  File "C:\Users\PatCa\anaconda3\lib\site-packages\starlette\middleware\errors.py", line 159, in __call__
    await self.app(scope, receive, _send)
  File "C:\Users\PatCa\anaconda3\lib\site-packages\starlette\exceptions.py", line 82, in __call__
    raise exc
  File "C:\Users\PatCa\anaconda3\lib\site-packages\starlette\exceptions.py", line 71, in __call__
    await self.app(scope, receive, sender)
  File "C:\Users\PatCa\anaconda3\lib\site-packages\starlette\routing.py", line 656, in __call__
    await route.handle(scope, receive, send)
  File "C:\Users\PatCa\anaconda3\lib\site-packages\starlette\routing.py", line 259, in handle
    await self.app(scope, receive, send)
  File "C:\Users\PatCa\anaconda3\lib\site-packages\starlette\routing.py", line 61, in app
    response = await func(request)
  File "C:\Users\PatCa\anaconda3\lib\site-packages\fastapi\routing.py", line 234, in app
    response_data = await serialize_response(
  File "C:\Users\PatCa\anaconda3\lib\site-packages\fastapi\routing.py", line 148, in serialize_response
    return jsonable_encoder(response_content)
  File "C:\Users\PatCa\anaconda3\lib\site-packages\fastapi\encoders.py", line 145, in jsonable_encoder
    return jsonable_encoder(
  File "C:\Users\PatCa\anaconda3\lib\site-packages\fastapi\encoders.py", line 93, in jsonable_encoder
    encoded_value = jsonable_encoder(
  File "C:\Users\PatCa\anaconda3\lib\site-packages\fastapi\encoders.py", line 145, in jsonable_encoder
    return jsonable_encoder(
  File "C:\Users\PatCa\anaconda3\lib\site-packages\fastapi\encoders.py", line 93, in jsonable_encoder
    encoded_value = jsonable_encoder(
  File "C:\Users\PatCa\anaconda3\lib\site-packages\fastapi\encoders.py", line 144, in jsonable_encoder
    raise ValueError(errors)
ValueError: [TypeError("'numpy.int64' object is not iterable"), TypeError('vars() argument must have __dict__ attribute')]
2022-01-12 11:20:22,068 INFO     Started server process [21172]
2022-01-12 11:20:22,068 INFO     Waiting for application startup.
2022-01-12 11:20:22,071 INFO     Application startup complete.
2022-01-12 11:20:24,836 INFO     Opened head circumference page
2022-01-12 11:20:24,905 ERROR    Exception in ASGI application
Traceback (most recent call last):
  File "C:\Users\PatCa\anaconda3\lib\site-packages\fastapi\encoders.py", line 137, in jsonable_encoder
    data = dict(obj)
TypeError: 'numpy.int64' object is not iterable

During handling of the above exception, another exception occurred:

Traceback (most recent call last):
  File "C:\Users\PatCa\anaconda3\lib\site-packages\fastapi\encoders.py", line 141, in jsonable_encoder
    data = vars(obj)
TypeError: vars() argument must have __dict__ attribute

During handling of the above exception, another exception occurred:

Traceback (most recent call last):
  File "C:\Users\PatCa\anaconda3\lib\site-packages\uvicorn\protocols\http\h11_impl.py", line 373, in run_asgi
    result = await app(self.scope, self.receive, self.send)
  File "C:\Users\PatCa\anaconda3\lib\site-packages\uvicorn\middleware\proxy_headers.py", line 75, in __call__
    return await self.app(scope, receive, send)
  File "C:\Users\PatCa\anaconda3\lib\site-packages\fastapi\applications.py", line 208, in __call__
    await super().__call__(scope, receive, send)
  File "C:\Users\PatCa\anaconda3\lib\site-packages\starlette\applications.py", line 112, in __call__
    await self.middleware_stack(scope, receive, send)
  File "C:\Users\PatCa\anaconda3\lib\site-packages\starlette\middleware\errors.py", line 181, in __call__
    raise exc
  File "C:\Users\PatCa\anaconda3\lib\site-packages\starlette\middleware\errors.py", line 159, in __call__
    await self.app(scope, receive, _send)
  File "C:\Users\PatCa\anaconda3\lib\site-packages\starlette\exceptions.py", line 82, in __call__
    raise exc
  File "C:\Users\PatCa\anaconda3\lib\site-packages\starlette\exceptions.py", line 71, in __call__
    await self.app(scope, receive, sender)
  File "C:\Users\PatCa\anaconda3\lib\site-packages\starlette\routing.py", line 656, in __call__
    await route.handle(scope, receive, send)
  File "C:\Users\PatCa\anaconda3\lib\site-packages\starlette\routing.py", line 259, in handle
    await self.app(scope, receive, send)
  File "C:\Users\PatCa\anaconda3\lib\site-packages\starlette\routing.py", line 61, in app
    response = await func(request)
  File "C:\Users\PatCa\anaconda3\lib\site-packages\fastapi\routing.py", line 234, in app
    response_data = await serialize_response(
  File "C:\Users\PatCa\anaconda3\lib\site-packages\fastapi\routing.py", line 148, in serialize_response
    return jsonable_encoder(response_content)
  File "C:\Users\PatCa\anaconda3\lib\site-packages\fastapi\encoders.py", line 93, in jsonable_encoder
    encoded_value = jsonable_encoder(
  File "C:\Users\PatCa\anaconda3\lib\site-packages\fastapi\encoders.py", line 145, in jsonable_encoder
    return jsonable_encoder(
  File "C:\Users\PatCa\anaconda3\lib\site-packages\fastapi\encoders.py", line 93, in jsonable_encoder
    encoded_value = jsonable_encoder(
  File "C:\Users\PatCa\anaconda3\lib\site-packages\fastapi\encoders.py", line 144, in jsonable_encoder
    raise ValueError(errors)
ValueError: [TypeError("'numpy.int64' object is not iterable"), TypeError('vars() argument must have __dict__ attribute')]
2022-01-12 11:21:20,974 INFO     Started server process [18260]
2022-01-12 11:21:20,974 INFO     Waiting for application startup.
2022-01-12 11:21:20,978 INFO     Application startup complete.
2022-01-12 11:21:21,964 INFO     Opened head circumference page
2022-01-12 11:21:54,960 INFO     Started server process [21456]
2022-01-12 11:21:54,960 INFO     Waiting for application startup.
2022-01-12 11:21:54,964 INFO     Application startup complete.
2022-01-12 11:22:00,802 INFO     Started server process [5284]
2022-01-12 11:22:00,803 INFO     Waiting for application startup.
2022-01-12 11:22:00,804 INFO     Application startup complete.
2022-01-12 11:22:03,555 INFO     Opened head circumference page
2022-01-12 11:22:03,618 ERROR    Exception in ASGI application
Traceback (most recent call last):
  File "C:\Users\PatCa\anaconda3\lib\site-packages\fastapi\encoders.py", line 137, in jsonable_encoder
    data = dict(obj)
TypeError: 'numpy.int64' object is not iterable

During handling of the above exception, another exception occurred:

Traceback (most recent call last):
  File "C:\Users\PatCa\anaconda3\lib\site-packages\fastapi\encoders.py", line 141, in jsonable_encoder
    data = vars(obj)
TypeError: vars() argument must have __dict__ attribute

During handling of the above exception, another exception occurred:

Traceback (most recent call last):
  File "C:\Users\PatCa\anaconda3\lib\site-packages\uvicorn\protocols\http\h11_impl.py", line 373, in run_asgi
    result = await app(self.scope, self.receive, self.send)
  File "C:\Users\PatCa\anaconda3\lib\site-packages\uvicorn\middleware\proxy_headers.py", line 75, in __call__
    return await self.app(scope, receive, send)
  File "C:\Users\PatCa\anaconda3\lib\site-packages\fastapi\applications.py", line 208, in __call__
    await super().__call__(scope, receive, send)
  File "C:\Users\PatCa\anaconda3\lib\site-packages\starlette\applications.py", line 112, in __call__
    await self.middleware_stack(scope, receive, send)
  File "C:\Users\PatCa\anaconda3\lib\site-packages\starlette\middleware\errors.py", line 181, in __call__
    raise exc
  File "C:\Users\PatCa\anaconda3\lib\site-packages\starlette\middleware\errors.py", line 159, in __call__
    await self.app(scope, receive, _send)
  File "C:\Users\PatCa\anaconda3\lib\site-packages\starlette\exceptions.py", line 82, in __call__
    raise exc
  File "C:\Users\PatCa\anaconda3\lib\site-packages\starlette\exceptions.py", line 71, in __call__
    await self.app(scope, receive, sender)
  File "C:\Users\PatCa\anaconda3\lib\site-packages\starlette\routing.py", line 656, in __call__
    await route.handle(scope, receive, send)
  File "C:\Users\PatCa\anaconda3\lib\site-packages\starlette\routing.py", line 259, in handle
    await self.app(scope, receive, send)
  File "C:\Users\PatCa\anaconda3\lib\site-packages\starlette\routing.py", line 61, in app
    response = await func(request)
  File "C:\Users\PatCa\anaconda3\lib\site-packages\fastapi\routing.py", line 234, in app
    response_data = await serialize_response(
  File "C:\Users\PatCa\anaconda3\lib\site-packages\fastapi\routing.py", line 148, in serialize_response
    return jsonable_encoder(response_content)
  File "C:\Users\PatCa\anaconda3\lib\site-packages\fastapi\encoders.py", line 93, in jsonable_encoder
    encoded_value = jsonable_encoder(
  File "C:\Users\PatCa\anaconda3\lib\site-packages\fastapi\encoders.py", line 145, in jsonable_encoder
    return jsonable_encoder(
  File "C:\Users\PatCa\anaconda3\lib\site-packages\fastapi\encoders.py", line 93, in jsonable_encoder
    encoded_value = jsonable_encoder(
  File "C:\Users\PatCa\anaconda3\lib\site-packages\fastapi\encoders.py", line 144, in jsonable_encoder
    raise ValueError(errors)
ValueError: [TypeError("'numpy.int64' object is not iterable"), TypeError('vars() argument must have __dict__ attribute')]
2022-01-12 11:22:12,030 INFO     Started server process [4420]
2022-01-12 11:22:12,030 INFO     Waiting for application startup.
2022-01-12 11:22:12,030 INFO     Application startup complete.
2022-01-12 11:22:27,907 INFO     Opened head circumference page
2022-01-12 11:25:36,915 INFO     Started server process [2988]
2022-01-12 11:25:36,916 INFO     Waiting for application startup.
2022-01-12 11:25:36,917 INFO     Application startup complete.
2022-01-12 11:25:40,455 INFO     Opened head circumference page
2022-01-12 11:25:53,369 INFO     Started server process [15912]
2022-01-12 11:25:53,370 INFO     Waiting for application startup.
2022-01-12 11:25:53,371 INFO     Application startup complete.
2022-01-12 11:25:56,171 INFO     Opened head circumference page
2022-01-12 11:26:07,975 INFO     Started server process [12952]
2022-01-12 11:26:07,975 INFO     Waiting for application startup.
2022-01-12 11:26:07,978 INFO     Application startup complete.
2022-01-12 11:26:10,410 INFO     Opened head circumference page
2022-01-12 11:26:32,745 INFO     Started server process [16972]
2022-01-12 11:26:32,745 INFO     Waiting for application startup.
2022-01-12 11:26:32,745 INFO     Application startup complete.
2022-01-12 11:26:35,653 INFO     Opened head circumference page
2022-01-12 11:27:01,942 INFO     Opened weight page
2022-01-12 11:27:35,860 INFO     Opened head circumference page
2022-01-12 11:28:59,524 INFO     Started server process [12956]
2022-01-12 11:28:59,524 INFO     Waiting for application startup.
2022-01-12 11:28:59,526 INFO     Application startup complete.
2022-01-12 11:29:02,377 INFO     Opened head circumference page
2022-01-12 11:29:24,480 INFO     Opened height page
2022-01-12 14:40:51,489 INFO     Started server process [16084]
2022-01-12 14:40:51,489 INFO     Waiting for application startup.
2022-01-12 14:40:51,497 INFO     Application startup complete.
2022-01-12 14:40:59,361 INFO     Opened height page
2022-01-12 14:41:20,723 INFO     Started server process [21432]
2022-01-12 14:41:20,723 INFO     Waiting for application startup.
2022-01-12 14:41:20,723 INFO     Application startup complete.
2022-01-12 14:41:20,850 INFO     Opened height page
2022-01-12 14:41:49,219 INFO     Opened height page
2022-01-12 14:41:49,253 ERROR    Exception in ASGI application
Traceback (most recent call last):
  File "C:\Users\PatCa\anaconda3\lib\site-packages\fastapi\encoders.py", line 137, in jsonable_encoder
    data = dict(obj)
TypeError: 'numpy.int64' object is not iterable

During handling of the above exception, another exception occurred:

Traceback (most recent call last):
  File "C:\Users\PatCa\anaconda3\lib\site-packages\fastapi\encoders.py", line 141, in jsonable_encoder
    data = vars(obj)
TypeError: vars() argument must have __dict__ attribute

During handling of the above exception, another exception occurred:

Traceback (most recent call last):
  File "C:\Users\PatCa\anaconda3\lib\site-packages\uvicorn\protocols\http\h11_impl.py", line 373, in run_asgi
    result = await app(self.scope, self.receive, self.send)
  File "C:\Users\PatCa\anaconda3\lib\site-packages\uvicorn\middleware\proxy_headers.py", line 75, in __call__
    return await self.app(scope, receive, send)
  File "C:\Users\PatCa\anaconda3\lib\site-packages\fastapi\applications.py", line 208, in __call__
    await super().__call__(scope, receive, send)
  File "C:\Users\PatCa\anaconda3\lib\site-packages\starlette\applications.py", line 112, in __call__
    await self.middleware_stack(scope, receive, send)
  File "C:\Users\PatCa\anaconda3\lib\site-packages\starlette\middleware\errors.py", line 181, in __call__
    raise exc
  File "C:\Users\PatCa\anaconda3\lib\site-packages\starlette\middleware\errors.py", line 159, in __call__
    await self.app(scope, receive, _send)
  File "C:\Users\PatCa\anaconda3\lib\site-packages\starlette\exceptions.py", line 82, in __call__
    raise exc
  File "C:\Users\PatCa\anaconda3\lib\site-packages\starlette\exceptions.py", line 71, in __call__
    await self.app(scope, receive, sender)
  File "C:\Users\PatCa\anaconda3\lib\site-packages\starlette\routing.py", line 656, in __call__
    await route.handle(scope, receive, send)
  File "C:\Users\PatCa\anaconda3\lib\site-packages\starlette\routing.py", line 259, in handle
    await self.app(scope, receive, send)
  File "C:\Users\PatCa\anaconda3\lib\site-packages\starlette\routing.py", line 61, in app
    response = await func(request)
  File "C:\Users\PatCa\anaconda3\lib\site-packages\fastapi\routing.py", line 234, in app
    response_data = await serialize_response(
  File "C:\Users\PatCa\anaconda3\lib\site-packages\fastapi\routing.py", line 148, in serialize_response
    return jsonable_encoder(response_content)
  File "C:\Users\PatCa\anaconda3\lib\site-packages\fastapi\encoders.py", line 93, in jsonable_encoder
    encoded_value = jsonable_encoder(
  File "C:\Users\PatCa\anaconda3\lib\site-packages\fastapi\encoders.py", line 145, in jsonable_encoder
    return jsonable_encoder(
  File "C:\Users\PatCa\anaconda3\lib\site-packages\fastapi\encoders.py", line 93, in jsonable_encoder
    encoded_value = jsonable_encoder(
  File "C:\Users\PatCa\anaconda3\lib\site-packages\fastapi\encoders.py", line 144, in jsonable_encoder
    raise ValueError(errors)
ValueError: [TypeError("'numpy.int64' object is not iterable"), TypeError('vars() argument must have __dict__ attribute')]
2022-01-12 14:43:53,212 INFO     Started server process [20740]
2022-01-12 14:43:53,216 INFO     Waiting for application startup.
2022-01-12 14:43:53,218 INFO     Application startup complete.
2022-01-12 14:44:44,742 INFO     Started server process [19688]
2022-01-12 14:44:44,743 INFO     Waiting for application startup.
2022-01-12 14:44:44,744 INFO     Application startup complete.
2022-01-12 14:44:54,706 INFO     Opened height page
2022-01-12 14:45:07,449 INFO     Started server process [20404]
2022-01-12 14:45:07,449 INFO     Waiting for application startup.
2022-01-12 14:45:07,455 INFO     Application startup complete.
2022-01-12 14:45:14,198 INFO     Opened head circumference page
2022-01-12 14:45:35,146 INFO     Started server process [18292]
2022-01-12 14:45:35,147 INFO     Waiting for application startup.
2022-01-12 14:45:35,148 INFO     Application startup complete.
2022-01-12 14:45:45,774 INFO     Shutting down
2022-01-12 14:48:01,780 INFO     Started server process [11568]
2022-01-12 14:48:01,783 INFO     Waiting for application startup.
2022-01-12 14:48:01,784 INFO     Application startup complete.
2022-01-12 14:56:27,035 INFO     Opened height page
2022-01-12 14:58:13,465 INFO     Opened head circumference page
2022-01-12 15:06:49,623 INFO     Opened weight page
2022-01-12 15:22:58,577 INFO     Opened weight page
2022-01-12 15:23:55,905 INFO     Opened weight page
2022-01-12 15:25:52,396 INFO     Opened head circumference page
2022-01-12 15:28:56,971 INFO     Opened weight page
2022-01-12 15:48:41,744 INFO     Opened height page
2022-01-12 15:49:04,696 INFO     Opened height page
2022-01-12 15:49:20,478 INFO     Opened height page
2022-01-12 15:49:46,684 INFO     Opened height page
2022-01-12 15:51:10,448 INFO     Opened height page
2022-01-12 15:52:30,852 INFO     Opened weight page
2022-01-12 15:52:44,987 INFO     Opened weight page
2022-01-12 15:53:30,408 INFO     Opened weight page
2022-01-12 15:54:21,624 INFO     Opened weight page
2022-01-12 15:55:54,991 INFO     Opened weight page
2022-01-12 15:56:26,468 INFO     Opened height page
2022-01-12 15:59:05,380 INFO     Opened head circumference page
2022-01-12 15:59:30,046 INFO     Opened head circumference page
2022-01-12 16:01:49,704 INFO     Opened weight page
2022-01-12 16:02:32,552 INFO     Opened weight page
2022-01-12 16:09:05,059 INFO     Opened weight page
2022-01-12 16:09:32,091 INFO     Opened weight page
2022-01-12 16:13:14,185 INFO     Opened weight page
2022-01-12 16:13:19,786 INFO     Opened weight page
2022-01-12 16:16:59,546 INFO     Opened weight page
2022-01-12 16:17:33,494 INFO     Opened weight page
2022-01-12 16:26:38,789 INFO     Opened weight page
2022-01-12 16:27:03,685 INFO     Opened weight page
2022-01-12 16:40:44,855 INFO     Opened weight page
2022-01-12 16:40:45,048 INFO     Opened height page
2022-01-12 16:40:45,194 INFO     Opened head circumference page
2022-01-12 16:46:10,281 INFO     Opened weight page
2022-01-12 16:46:10,316 INFO     Opened height page
2022-01-12 16:47:10,171 INFO     Opened weight page
2022-01-12 16:47:10,206 INFO     Opened height page
2022-01-12 16:47:37,778 INFO     Opened weight page
2022-01-12 16:47:37,827 INFO     Opened height page
2022-01-12 16:48:43,364 INFO     Opened weight page
2022-01-12 16:48:43,397 INFO     Opened height page
2022-01-12 16:48:53,731 INFO     Opened weight page
2022-01-12 16:48:53,765 INFO     Opened height page
2022-01-12 16:50:27,393 INFO     Opened weight page
2022-01-12 16:50:27,438 INFO     Opened height page
2022-01-12 16:51:38,985 INFO     Opened weight page
2022-01-12 16:51:39,180 INFO     Opened height page
2022-01-12 16:51:39,319 INFO     Opened head circumference page
2022-01-12 16:53:27,730 INFO     Opened weight page
2022-01-12 16:53:27,918 INFO     Opened height page
2022-01-12 16:53:28,068 INFO     Opened head circumference page
2022-01-12 16:56:05,110 INFO     Opened weight page
2022-01-12 16:56:05,315 INFO     Opened height page
2022-01-12 16:56:05,460 INFO     Opened head circumference page
2022-01-12 16:56:18,198 INFO     Opened weight page
2022-01-12 16:56:18,386 INFO     Opened height page
2022-01-12 16:56:18,548 INFO     Opened head circumference page
2022-01-13 15:55:05,666 INFO     Started server process [2588]
2022-01-13 15:55:05,675 INFO     Waiting for application startup.
2022-01-13 15:55:05,676 INFO     Application startup complete.
2022-01-13 16:33:04,862 INFO     Started server process [7140]
2022-01-13 16:33:04,869 INFO     Waiting for application startup.
2022-01-13 16:33:04,869 INFO     Application startup complete.
2022-01-13 16:33:48,575 INFO     Opened favicon
2022-01-13 16:33:48,885 ERROR    Exception in ASGI application
Traceback (most recent call last):
  File "C:\Users\PatCa\anaconda3\lib\site-packages\starlette\responses.py", line 282, in __call__
    stat_result = await anyio.to_thread.run_sync(os.stat, self.path)
  File "C:\Users\PatCa\anaconda3\lib\site-packages\anyio\to_thread.py", line 28, in run_sync
    return await get_asynclib().run_sync_in_worker_thread(func, *args, cancellable=cancellable,
  File "C:\Users\PatCa\anaconda3\lib\site-packages\anyio\_backends\_asyncio.py", line 805, in run_sync_in_worker_thread
    return await future
  File "C:\Users\PatCa\anaconda3\lib\site-packages\anyio\_backends\_asyncio.py", line 743, in run
    result = func(*args)
FileNotFoundError: [WinError 2] The system cannot find the file specified: 'favicon.ico'

During handling of the above exception, another exception occurred:

Traceback (most recent call last):
  File "C:\Users\PatCa\anaconda3\lib\site-packages\uvicorn\protocols\http\h11_impl.py", line 373, in run_asgi
    result = await app(self.scope, self.receive, self.send)
  File "C:\Users\PatCa\anaconda3\lib\site-packages\uvicorn\middleware\proxy_headers.py", line 75, in __call__
    return await self.app(scope, receive, send)
  File "C:\Users\PatCa\anaconda3\lib\site-packages\fastapi\applications.py", line 208, in __call__
    await super().__call__(scope, receive, send)
  File "C:\Users\PatCa\anaconda3\lib\site-packages\starlette\applications.py", line 112, in __call__
    await self.middleware_stack(scope, receive, send)
  File "C:\Users\PatCa\anaconda3\lib\site-packages\starlette\middleware\errors.py", line 181, in __call__
    raise exc
  File "C:\Users\PatCa\anaconda3\lib\site-packages\starlette\middleware\errors.py", line 159, in __call__
    await self.app(scope, receive, _send)
  File "C:\Users\PatCa\anaconda3\lib\site-packages\starlette\exceptions.py", line 82, in __call__
    raise exc
  File "C:\Users\PatCa\anaconda3\lib\site-packages\starlette\exceptions.py", line 71, in __call__
    await self.app(scope, receive, sender)
  File "C:\Users\PatCa\anaconda3\lib\site-packages\starlette\routing.py", line 656, in __call__
    await route.handle(scope, receive, send)
  File "C:\Users\PatCa\anaconda3\lib\site-packages\starlette\routing.py", line 259, in handle
    await self.app(scope, receive, send)
  File "C:\Users\PatCa\anaconda3\lib\site-packages\starlette\routing.py", line 64, in app
    await response(scope, receive, send)
  File "C:\Users\PatCa\anaconda3\lib\site-packages\starlette\responses.py", line 285, in __call__
    raise RuntimeError(f"File at path {self.path} does not exist.")
RuntimeError: File at path favicon.ico does not exist.
2022-01-13 16:34:20,245 INFO     Opened weight page
2022-01-13 16:34:20,565 INFO     Opened height page
2022-01-13 16:34:20,734 INFO     Opened head circumference page
2022-01-13 16:56:21,051 INFO     Started server process [10692]
2022-01-13 16:56:21,052 INFO     Waiting for application startup.
2022-01-13 16:56:21,053 INFO     Application startup complete.
2022-01-13 16:56:43,544 INFO     Started server process [4956]
2022-01-13 16:56:43,545 INFO     Waiting for application startup.
2022-01-13 16:56:43,546 INFO     Application startup complete.
2022-01-13 16:56:47,907 INFO     Opened feeding page
2022-01-13 16:56:47,930 ERROR    Exception in ASGI application
Traceback (most recent call last):
  File "C:\Users\PatCa\anaconda3\lib\site-packages\fastapi\encoders.py", line 137, in jsonable_encoder
    data = dict(obj)
TypeError: 'numpy.int64' object is not iterable

During handling of the above exception, another exception occurred:

Traceback (most recent call last):
  File "C:\Users\PatCa\anaconda3\lib\site-packages\fastapi\encoders.py", line 141, in jsonable_encoder
    data = vars(obj)
TypeError: vars() argument must have __dict__ attribute

During handling of the above exception, another exception occurred:

Traceback (most recent call last):
  File "C:\Users\PatCa\anaconda3\lib\site-packages\uvicorn\protocols\http\h11_impl.py", line 373, in run_asgi
    result = await app(self.scope, self.receive, self.send)
  File "C:\Users\PatCa\anaconda3\lib\site-packages\uvicorn\middleware\proxy_headers.py", line 75, in __call__
    return await self.app(scope, receive, send)
  File "C:\Users\PatCa\anaconda3\lib\site-packages\fastapi\applications.py", line 208, in __call__
    await super().__call__(scope, receive, send)
  File "C:\Users\PatCa\anaconda3\lib\site-packages\starlette\applications.py", line 112, in __call__
    await self.middleware_stack(scope, receive, send)
  File "C:\Users\PatCa\anaconda3\lib\site-packages\starlette\middleware\errors.py", line 181, in __call__
    raise exc
  File "C:\Users\PatCa\anaconda3\lib\site-packages\starlette\middleware\errors.py", line 159, in __call__
    await self.app(scope, receive, _send)
  File "C:\Users\PatCa\anaconda3\lib\site-packages\starlette\exceptions.py", line 82, in __call__
    raise exc
  File "C:\Users\PatCa\anaconda3\lib\site-packages\starlette\exceptions.py", line 71, in __call__
    await self.app(scope, receive, sender)
  File "C:\Users\PatCa\anaconda3\lib\site-packages\starlette\routing.py", line 656, in __call__
    await route.handle(scope, receive, send)
  File "C:\Users\PatCa\anaconda3\lib\site-packages\starlette\routing.py", line 259, in handle
    await self.app(scope, receive, send)
  File "C:\Users\PatCa\anaconda3\lib\site-packages\starlette\routing.py", line 61, in app
    response = await func(request)
  File "C:\Users\PatCa\anaconda3\lib\site-packages\fastapi\routing.py", line 234, in app
    response_data = await serialize_response(
  File "C:\Users\PatCa\anaconda3\lib\site-packages\fastapi\routing.py", line 148, in serialize_response
    return jsonable_encoder(response_content)
  File "C:\Users\PatCa\anaconda3\lib\site-packages\fastapi\encoders.py", line 93, in jsonable_encoder
    encoded_value = jsonable_encoder(
  File "C:\Users\PatCa\anaconda3\lib\site-packages\fastapi\encoders.py", line 145, in jsonable_encoder
    return jsonable_encoder(
  File "C:\Users\PatCa\anaconda3\lib\site-packages\fastapi\encoders.py", line 93, in jsonable_encoder
    encoded_value = jsonable_encoder(
  File "C:\Users\PatCa\anaconda3\lib\site-packages\fastapi\encoders.py", line 144, in jsonable_encoder
    raise ValueError(errors)
ValueError: [TypeError("'numpy.int64' object is not iterable"), TypeError('vars() argument must have __dict__ attribute')]
2022-01-13 16:56:48,003 INFO     Opened favicon
2022-01-13 16:56:48,306 ERROR    Exception in ASGI application
Traceback (most recent call last):
  File "C:\Users\PatCa\anaconda3\lib\site-packages\starlette\responses.py", line 282, in __call__
    stat_result = await anyio.to_thread.run_sync(os.stat, self.path)
  File "C:\Users\PatCa\anaconda3\lib\site-packages\anyio\to_thread.py", line 28, in run_sync
    return await get_asynclib().run_sync_in_worker_thread(func, *args, cancellable=cancellable,
  File "C:\Users\PatCa\anaconda3\lib\site-packages\anyio\_backends\_asyncio.py", line 805, in run_sync_in_worker_thread
    return await future
  File "C:\Users\PatCa\anaconda3\lib\site-packages\anyio\_backends\_asyncio.py", line 743, in run
    result = func(*args)
FileNotFoundError: [WinError 2] The system cannot find the file specified: 'favicon.ico'

During handling of the above exception, another exception occurred:

Traceback (most recent call last):
  File "C:\Users\PatCa\anaconda3\lib\site-packages\uvicorn\protocols\http\h11_impl.py", line 373, in run_asgi
    result = await app(self.scope, self.receive, self.send)
  File "C:\Users\PatCa\anaconda3\lib\site-packages\uvicorn\middleware\proxy_headers.py", line 75, in __call__
    return await self.app(scope, receive, send)
  File "C:\Users\PatCa\anaconda3\lib\site-packages\fastapi\applications.py", line 208, in __call__
    await super().__call__(scope, receive, send)
  File "C:\Users\PatCa\anaconda3\lib\site-packages\starlette\applications.py", line 112, in __call__
    await self.middleware_stack(scope, receive, send)
  File "C:\Users\PatCa\anaconda3\lib\site-packages\starlette\middleware\errors.py", line 181, in __call__
    raise exc
  File "C:\Users\PatCa\anaconda3\lib\site-packages\starlette\middleware\errors.py", line 159, in __call__
    await self.app(scope, receive, _send)
  File "C:\Users\PatCa\anaconda3\lib\site-packages\starlette\exceptions.py", line 82, in __call__
    raise exc
  File "C:\Users\PatCa\anaconda3\lib\site-packages\starlette\exceptions.py", line 71, in __call__
    await self.app(scope, receive, sender)
  File "C:\Users\PatCa\anaconda3\lib\site-packages\starlette\routing.py", line 656, in __call__
    await route.handle(scope, receive, send)
  File "C:\Users\PatCa\anaconda3\lib\site-packages\starlette\routing.py", line 259, in handle
    await self.app(scope, receive, send)
  File "C:\Users\PatCa\anaconda3\lib\site-packages\starlette\routing.py", line 64, in app
    await response(scope, receive, send)
  File "C:\Users\PatCa\anaconda3\lib\site-packages\starlette\responses.py", line 285, in __call__
    raise RuntimeError(f"File at path {self.path} does not exist.")
RuntimeError: File at path favicon.ico does not exist.
2022-01-13 16:58:25,737 INFO     Started server process [1312]
2022-01-13 16:58:25,738 INFO     Waiting for application startup.
2022-01-13 16:58:25,738 INFO     Application startup complete.
2022-01-13 16:58:31,589 INFO     Opened feeding page
2022-01-13 16:58:31,606 ERROR    Exception in ASGI application
Traceback (most recent call last):
  File "C:\Users\PatCa\anaconda3\lib\site-packages\fastapi\encoders.py", line 137, in jsonable_encoder
    data = dict(obj)
TypeError: 'numpy.int64' object is not iterable

During handling of the above exception, another exception occurred:

Traceback (most recent call last):
  File "C:\Users\PatCa\anaconda3\lib\site-packages\fastapi\encoders.py", line 141, in jsonable_encoder
    data = vars(obj)
TypeError: vars() argument must have __dict__ attribute

During handling of the above exception, another exception occurred:

Traceback (most recent call last):
  File "C:\Users\PatCa\anaconda3\lib\site-packages\uvicorn\protocols\http\h11_impl.py", line 373, in run_asgi
    result = await app(self.scope, self.receive, self.send)
  File "C:\Users\PatCa\anaconda3\lib\site-packages\uvicorn\middleware\proxy_headers.py", line 75, in __call__
    return await self.app(scope, receive, send)
  File "C:\Users\PatCa\anaconda3\lib\site-packages\fastapi\applications.py", line 208, in __call__
    await super().__call__(scope, receive, send)
  File "C:\Users\PatCa\anaconda3\lib\site-packages\starlette\applications.py", line 112, in __call__
    await self.middleware_stack(scope, receive, send)
  File "C:\Users\PatCa\anaconda3\lib\site-packages\starlette\middleware\errors.py", line 181, in __call__
    raise exc
  File "C:\Users\PatCa\anaconda3\lib\site-packages\starlette\middleware\errors.py", line 159, in __call__
    await self.app(scope, receive, _send)
  File "C:\Users\PatCa\anaconda3\lib\site-packages\starlette\exceptions.py", line 82, in __call__
    raise exc
  File "C:\Users\PatCa\anaconda3\lib\site-packages\starlette\exceptions.py", line 71, in __call__
    await self.app(scope, receive, sender)
  File "C:\Users\PatCa\anaconda3\lib\site-packages\starlette\routing.py", line 656, in __call__
    await route.handle(scope, receive, send)
  File "C:\Users\PatCa\anaconda3\lib\site-packages\starlette\routing.py", line 259, in handle
    await self.app(scope, receive, send)
  File "C:\Users\PatCa\anaconda3\lib\site-packages\starlette\routing.py", line 61, in app
    response = await func(request)
  File "C:\Users\PatCa\anaconda3\lib\site-packages\fastapi\routing.py", line 234, in app
    response_data = await serialize_response(
  File "C:\Users\PatCa\anaconda3\lib\site-packages\fastapi\routing.py", line 148, in serialize_response
    return jsonable_encoder(response_content)
  File "C:\Users\PatCa\anaconda3\lib\site-packages\fastapi\encoders.py", line 93, in jsonable_encoder
    encoded_value = jsonable_encoder(
  File "C:\Users\PatCa\anaconda3\lib\site-packages\fastapi\encoders.py", line 145, in jsonable_encoder
    return jsonable_encoder(
  File "C:\Users\PatCa\anaconda3\lib\site-packages\fastapi\encoders.py", line 93, in jsonable_encoder
    encoded_value = jsonable_encoder(
  File "C:\Users\PatCa\anaconda3\lib\site-packages\fastapi\encoders.py", line 144, in jsonable_encoder
    raise ValueError(errors)
ValueError: [TypeError("'numpy.int64' object is not iterable"), TypeError('vars() argument must have __dict__ attribute')]
2022-01-13 16:58:31,638 INFO     Opened favicon
2022-01-13 16:58:31,946 ERROR    Exception in ASGI application
Traceback (most recent call last):
  File "C:\Users\PatCa\anaconda3\lib\site-packages\starlette\responses.py", line 282, in __call__
    stat_result = await anyio.to_thread.run_sync(os.stat, self.path)
  File "C:\Users\PatCa\anaconda3\lib\site-packages\anyio\to_thread.py", line 28, in run_sync
    return await get_asynclib().run_sync_in_worker_thread(func, *args, cancellable=cancellable,
  File "C:\Users\PatCa\anaconda3\lib\site-packages\anyio\_backends\_asyncio.py", line 805, in run_sync_in_worker_thread
    return await future
  File "C:\Users\PatCa\anaconda3\lib\site-packages\anyio\_backends\_asyncio.py", line 743, in run
    result = func(*args)
FileNotFoundError: [WinError 2] The system cannot find the file specified: 'C:\\Users\\PatCa\\Documents\\PythonScripts\\baby_growth\\data_service\\data\\favicon.png'

During handling of the above exception, another exception occurred:

Traceback (most recent call last):
  File "C:\Users\PatCa\anaconda3\lib\site-packages\uvicorn\protocols\http\h11_impl.py", line 373, in run_asgi
    result = await app(self.scope, self.receive, self.send)
  File "C:\Users\PatCa\anaconda3\lib\site-packages\uvicorn\middleware\proxy_headers.py", line 75, in __call__
    return await self.app(scope, receive, send)
  File "C:\Users\PatCa\anaconda3\lib\site-packages\fastapi\applications.py", line 208, in __call__
    await super().__call__(scope, receive, send)
  File "C:\Users\PatCa\anaconda3\lib\site-packages\starlette\applications.py", line 112, in __call__
    await self.middleware_stack(scope, receive, send)
  File "C:\Users\PatCa\anaconda3\lib\site-packages\starlette\middleware\errors.py", line 181, in __call__
    raise exc
  File "C:\Users\PatCa\anaconda3\lib\site-packages\starlette\middleware\errors.py", line 159, in __call__
    await self.app(scope, receive, _send)
  File "C:\Users\PatCa\anaconda3\lib\site-packages\starlette\exceptions.py", line 82, in __call__
    raise exc
  File "C:\Users\PatCa\anaconda3\lib\site-packages\starlette\exceptions.py", line 71, in __call__
    await self.app(scope, receive, sender)
  File "C:\Users\PatCa\anaconda3\lib\site-packages\starlette\routing.py", line 656, in __call__
    await route.handle(scope, receive, send)
  File "C:\Users\PatCa\anaconda3\lib\site-packages\starlette\routing.py", line 259, in handle
    await self.app(scope, receive, send)
  File "C:\Users\PatCa\anaconda3\lib\site-packages\starlette\routing.py", line 64, in app
    await response(scope, receive, send)
  File "C:\Users\PatCa\anaconda3\lib\site-packages\starlette\responses.py", line 285, in __call__
    raise RuntimeError(f"File at path {self.path} does not exist.")
RuntimeError: File at path C:\Users\PatCa\Documents\PythonScripts\baby_growth\data_service\data\favicon.png does not exist.
2022-01-13 16:58:54,869 INFO     Opened weight page
2022-01-13 16:58:54,973 INFO     Opened favicon
2022-01-13 16:58:54,977 ERROR    Exception in ASGI application
Traceback (most recent call last):
  File "C:\Users\PatCa\anaconda3\lib\site-packages\starlette\responses.py", line 282, in __call__
    stat_result = await anyio.to_thread.run_sync(os.stat, self.path)
  File "C:\Users\PatCa\anaconda3\lib\site-packages\anyio\to_thread.py", line 28, in run_sync
    return await get_asynclib().run_sync_in_worker_thread(func, *args, cancellable=cancellable,
  File "C:\Users\PatCa\anaconda3\lib\site-packages\anyio\_backends\_asyncio.py", line 805, in run_sync_in_worker_thread
    return await future
  File "C:\Users\PatCa\anaconda3\lib\site-packages\anyio\_backends\_asyncio.py", line 743, in run
    result = func(*args)
FileNotFoundError: [WinError 2] The system cannot find the file specified: 'C:\\Users\\PatCa\\Documents\\PythonScripts\\baby_growth\\data_service\\data\\favicon.png'

During handling of the above exception, another exception occurred:

Traceback (most recent call last):
  File "C:\Users\PatCa\anaconda3\lib\site-packages\uvicorn\protocols\http\h11_impl.py", line 373, in run_asgi
    result = await app(self.scope, self.receive, self.send)
  File "C:\Users\PatCa\anaconda3\lib\site-packages\uvicorn\middleware\proxy_headers.py", line 75, in __call__
    return await self.app(scope, receive, send)
  File "C:\Users\PatCa\anaconda3\lib\site-packages\fastapi\applications.py", line 208, in __call__
    await super().__call__(scope, receive, send)
  File "C:\Users\PatCa\anaconda3\lib\site-packages\starlette\applications.py", line 112, in __call__
    await self.middleware_stack(scope, receive, send)
  File "C:\Users\PatCa\anaconda3\lib\site-packages\starlette\middleware\errors.py", line 181, in __call__
    raise exc
  File "C:\Users\PatCa\anaconda3\lib\site-packages\starlette\middleware\errors.py", line 159, in __call__
    await self.app(scope, receive, _send)
  File "C:\Users\PatCa\anaconda3\lib\site-packages\starlette\exceptions.py", line 82, in __call__
    raise exc
  File "C:\Users\PatCa\anaconda3\lib\site-packages\starlette\exceptions.py", line 71, in __call__
    await self.app(scope, receive, sender)
  File "C:\Users\PatCa\anaconda3\lib\site-packages\starlette\routing.py", line 656, in __call__
    await route.handle(scope, receive, send)
  File "C:\Users\PatCa\anaconda3\lib\site-packages\starlette\routing.py", line 259, in handle
    await self.app(scope, receive, send)
  File "C:\Users\PatCa\anaconda3\lib\site-packages\starlette\routing.py", line 64, in app
    await response(scope, receive, send)
  File "C:\Users\PatCa\anaconda3\lib\site-packages\starlette\responses.py", line 285, in __call__
    raise RuntimeError(f"File at path {self.path} does not exist.")
RuntimeError: File at path C:\Users\PatCa\Documents\PythonScripts\baby_growth\data_service\data\favicon.png does not exist.
2022-01-13 16:59:54,028 INFO     Started server process [9532]
2022-01-13 16:59:54,029 INFO     Waiting for application startup.
2022-01-13 16:59:54,030 INFO     Application startup complete.
2022-01-13 16:59:59,897 INFO     Started server process [8648]
2022-01-13 16:59:59,898 INFO     Waiting for application startup.
2022-01-13 16:59:59,899 INFO     Application startup complete.
2022-01-13 17:00:08,742 INFO     Opened feeding page
2022-01-13 17:00:08,808 INFO     Opened favicon
2022-01-13 17:00:09,122 ERROR    Exception in ASGI application
Traceback (most recent call last):
  File "C:\Users\PatCa\anaconda3\lib\site-packages\starlette\responses.py", line 282, in __call__
    stat_result = await anyio.to_thread.run_sync(os.stat, self.path)
  File "C:\Users\PatCa\anaconda3\lib\site-packages\anyio\to_thread.py", line 28, in run_sync
    return await get_asynclib().run_sync_in_worker_thread(func, *args, cancellable=cancellable,
  File "C:\Users\PatCa\anaconda3\lib\site-packages\anyio\_backends\_asyncio.py", line 805, in run_sync_in_worker_thread
    return await future
  File "C:\Users\PatCa\anaconda3\lib\site-packages\anyio\_backends\_asyncio.py", line 743, in run
    result = func(*args)
FileNotFoundError: [WinError 2] The system cannot find the file specified: 'C:\\Users\\PatCa\\Documents\\PythonScripts\\baby_growth\\data_service\\data\\favicon.png'

During handling of the above exception, another exception occurred:

Traceback (most recent call last):
  File "C:\Users\PatCa\anaconda3\lib\site-packages\uvicorn\protocols\http\h11_impl.py", line 373, in run_asgi
    result = await app(self.scope, self.receive, self.send)
  File "C:\Users\PatCa\anaconda3\lib\site-packages\uvicorn\middleware\proxy_headers.py", line 75, in __call__
    return await self.app(scope, receive, send)
  File "C:\Users\PatCa\anaconda3\lib\site-packages\fastapi\applications.py", line 208, in __call__
    await super().__call__(scope, receive, send)
  File "C:\Users\PatCa\anaconda3\lib\site-packages\starlette\applications.py", line 112, in __call__
    await self.middleware_stack(scope, receive, send)
  File "C:\Users\PatCa\anaconda3\lib\site-packages\starlette\middleware\errors.py", line 181, in __call__
    raise exc
  File "C:\Users\PatCa\anaconda3\lib\site-packages\starlette\middleware\errors.py", line 159, in __call__
    await self.app(scope, receive, _send)
  File "C:\Users\PatCa\anaconda3\lib\site-packages\starlette\exceptions.py", line 82, in __call__
    raise exc
  File "C:\Users\PatCa\anaconda3\lib\site-packages\starlette\exceptions.py", line 71, in __call__
    await self.app(scope, receive, sender)
  File "C:\Users\PatCa\anaconda3\lib\site-packages\starlette\routing.py", line 656, in __call__
    await route.handle(scope, receive, send)
  File "C:\Users\PatCa\anaconda3\lib\site-packages\starlette\routing.py", line 259, in handle
    await self.app(scope, receive, send)
  File "C:\Users\PatCa\anaconda3\lib\site-packages\starlette\routing.py", line 64, in app
    await response(scope, receive, send)
  File "C:\Users\PatCa\anaconda3\lib\site-packages\starlette\responses.py", line 285, in __call__
    raise RuntimeError(f"File at path {self.path} does not exist.")
RuntimeError: File at path C:\Users\PatCa\Documents\PythonScripts\baby_growth\data_service\data\favicon.png does not exist.
2022-01-13 17:00:48,499 INFO     Opened feeding page
2022-01-13 17:00:48,553 INFO     Opened favicon
2022-01-13 17:01:08,229 INFO     Started server process [2768]
2022-01-13 17:01:08,231 INFO     Waiting for application startup.
2022-01-13 17:01:08,231 INFO     Application startup complete.
2022-01-13 17:01:10,536 INFO     Opened feeding page
2022-01-13 17:01:10,568 ERROR    Exception in ASGI application
Traceback (most recent call last):
  File "C:\Users\PatCa\anaconda3\lib\site-packages\fastapi\encoders.py", line 137, in jsonable_encoder
    data = dict(obj)
TypeError: 'numpy.int64' object is not iterable

During handling of the above exception, another exception occurred:

Traceback (most recent call last):
  File "C:\Users\PatCa\anaconda3\lib\site-packages\fastapi\encoders.py", line 141, in jsonable_encoder
    data = vars(obj)
TypeError: vars() argument must have __dict__ attribute

During handling of the above exception, another exception occurred:

Traceback (most recent call last):
  File "C:\Users\PatCa\anaconda3\lib\site-packages\uvicorn\protocols\http\h11_impl.py", line 373, in run_asgi
    result = await app(self.scope, self.receive, self.send)
  File "C:\Users\PatCa\anaconda3\lib\site-packages\uvicorn\middleware\proxy_headers.py", line 75, in __call__
    return await self.app(scope, receive, send)
  File "C:\Users\PatCa\anaconda3\lib\site-packages\fastapi\applications.py", line 208, in __call__
    await super().__call__(scope, receive, send)
  File "C:\Users\PatCa\anaconda3\lib\site-packages\starlette\applications.py", line 112, in __call__
    await self.middleware_stack(scope, receive, send)
  File "C:\Users\PatCa\anaconda3\lib\site-packages\starlette\middleware\errors.py", line 181, in __call__
    raise exc
  File "C:\Users\PatCa\anaconda3\lib\site-packages\starlette\middleware\errors.py", line 159, in __call__
    await self.app(scope, receive, _send)
  File "C:\Users\PatCa\anaconda3\lib\site-packages\starlette\exceptions.py", line 82, in __call__
    raise exc
  File "C:\Users\PatCa\anaconda3\lib\site-packages\starlette\exceptions.py", line 71, in __call__
    await self.app(scope, receive, sender)
  File "C:\Users\PatCa\anaconda3\lib\site-packages\starlette\routing.py", line 656, in __call__
    await route.handle(scope, receive, send)
  File "C:\Users\PatCa\anaconda3\lib\site-packages\starlette\routing.py", line 259, in handle
    await self.app(scope, receive, send)
  File "C:\Users\PatCa\anaconda3\lib\site-packages\starlette\routing.py", line 61, in app
    response = await func(request)
  File "C:\Users\PatCa\anaconda3\lib\site-packages\fastapi\routing.py", line 234, in app
    response_data = await serialize_response(
  File "C:\Users\PatCa\anaconda3\lib\site-packages\fastapi\routing.py", line 148, in serialize_response
    return jsonable_encoder(response_content)
  File "C:\Users\PatCa\anaconda3\lib\site-packages\fastapi\encoders.py", line 93, in jsonable_encoder
    encoded_value = jsonable_encoder(
  File "C:\Users\PatCa\anaconda3\lib\site-packages\fastapi\encoders.py", line 145, in jsonable_encoder
    return jsonable_encoder(
  File "C:\Users\PatCa\anaconda3\lib\site-packages\fastapi\encoders.py", line 93, in jsonable_encoder
    encoded_value = jsonable_encoder(
  File "C:\Users\PatCa\anaconda3\lib\site-packages\fastapi\encoders.py", line 144, in jsonable_encoder
    raise ValueError(errors)
ValueError: [TypeError("'numpy.int64' object is not iterable"), TypeError('vars() argument must have __dict__ attribute')]
2022-01-13 17:10:53,541 INFO     Started server process [2540]
2022-01-13 17:10:53,541 INFO     Waiting for application startup.
2022-01-13 17:10:53,541 INFO     Application startup complete.
2022-01-13 17:12:05,331 INFO     Started server process [9172]
2022-01-13 17:12:05,332 INFO     Waiting for application startup.
2022-01-13 17:12:05,333 INFO     Application startup complete.
2022-01-13 17:12:14,311 INFO     Opened feeding page
2022-01-13 17:16:05,147 INFO     Started server process [1220]
2022-01-13 17:16:05,148 INFO     Waiting for application startup.
2022-01-13 17:16:05,149 INFO     Application startup complete.
2022-01-13 17:16:09,532 INFO     Opened feeding page
2022-01-13 17:17:40,896 INFO     Shutting down
2022-01-13 17:18:19,255 INFO     Started server process [596]
2022-01-13 17:18:19,255 INFO     Waiting for application startup.
2022-01-13 17:18:19,259 INFO     Application startup complete.
2022-01-13 17:18:24,032 INFO     Opened feeding page
2022-01-13 17:18:49,053 INFO     Opened feeding page
2022-01-13 17:21:53,306 INFO     Started server process [13640]
2022-01-13 17:21:53,307 INFO     Waiting for application startup.
2022-01-13 17:21:53,308 INFO     Application startup complete.
2022-01-13 17:22:17,761 INFO     Opened feeding page
2022-01-13 17:25:35,449 INFO     Opened feeding page
2022-01-13 17:28:35,517 INFO     Started server process [8296]
2022-01-13 17:28:35,517 INFO     Waiting for application startup.
2022-01-13 17:28:35,517 INFO     Application startup complete.
2022-01-13 17:28:42,583 INFO     Opened feeding page
2022-01-13 17:28:42,779 ERROR    Exception in ASGI application
Traceback (most recent call last):
  File "C:\Users\PatCa\anaconda3\lib\site-packages\uvicorn\protocols\http\h11_impl.py", line 373, in run_asgi
    result = await app(self.scope, self.receive, self.send)
  File "C:\Users\PatCa\anaconda3\lib\site-packages\uvicorn\middleware\proxy_headers.py", line 75, in __call__
    return await self.app(scope, receive, send)
  File "C:\Users\PatCa\anaconda3\lib\site-packages\fastapi\applications.py", line 208, in __call__
    await super().__call__(scope, receive, send)
  File "C:\Users\PatCa\anaconda3\lib\site-packages\starlette\applications.py", line 112, in __call__
    await self.middleware_stack(scope, receive, send)
  File "C:\Users\PatCa\anaconda3\lib\site-packages\starlette\middleware\errors.py", line 181, in __call__
    raise exc
  File "C:\Users\PatCa\anaconda3\lib\site-packages\starlette\middleware\errors.py", line 159, in __call__
    await self.app(scope, receive, _send)
  File "C:\Users\PatCa\anaconda3\lib\site-packages\starlette\exceptions.py", line 82, in __call__
    raise exc
  File "C:\Users\PatCa\anaconda3\lib\site-packages\starlette\exceptions.py", line 71, in __call__
    await self.app(scope, receive, sender)
  File "C:\Users\PatCa\anaconda3\lib\site-packages\starlette\routing.py", line 656, in __call__
    await route.handle(scope, receive, send)
  File "C:\Users\PatCa\anaconda3\lib\site-packages\starlette\routing.py", line 259, in handle
    await self.app(scope, receive, send)
  File "C:\Users\PatCa\anaconda3\lib\site-packages\starlette\routing.py", line 61, in app
    response = await func(request)
  File "C:\Users\PatCa\anaconda3\lib\site-packages\fastapi\routing.py", line 226, in app
    raw_response = await run_endpoint_function(
  File "C:\Users\PatCa\anaconda3\lib\site-packages\fastapi\routing.py", line 161, in run_endpoint_function
    return await run_in_threadpool(dependant.call, **values)
  File "C:\Users\PatCa\anaconda3\lib\site-packages\starlette\concurrency.py", line 39, in run_in_threadpool
    return await anyio.to_thread.run_sync(func, *args)
  File "C:\Users\PatCa\anaconda3\lib\site-packages\anyio\to_thread.py", line 28, in run_sync
    return await get_asynclib().run_sync_in_worker_thread(func, *args, cancellable=cancellable,
  File "C:\Users\PatCa\anaconda3\lib\site-packages\anyio\_backends\_asyncio.py", line 805, in run_sync_in_worker_thread
    return await future
  File "C:\Users\PatCa\anaconda3\lib\site-packages\anyio\_backends\_asyncio.py", line 743, in run
    result = func(*args)
  File ".\app\main.py", line 72, in feeding
    return result.to_json
AttributeError: 'dict' object has no attribute 'to_json'
2022-01-13 17:28:58,854 INFO     Started server process [15736]
2022-01-13 17:28:58,854 INFO     Waiting for application startup.
2022-01-13 17:28:58,854 INFO     Application startup complete.
2022-01-13 17:29:02,152 INFO     Opened feeding page
2022-01-13 17:29:22,292 INFO     Started server process [1276]
2022-01-13 17:29:22,293 INFO     Waiting for application startup.
2022-01-13 17:29:22,294 INFO     Application startup complete.
2022-01-13 17:29:25,529 INFO     Opened feeding page
2022-01-13 17:29:52,778 INFO     Started server process [15952]
2022-01-13 17:29:52,778 INFO     Waiting for application startup.
2022-01-13 17:29:52,783 INFO     Application startup complete.
2022-01-13 17:29:56,349 INFO     Opened feeding page
2022-01-13 17:29:56,555 ERROR    Exception in ASGI application
Traceback (most recent call last):
  File "C:\Users\PatCa\anaconda3\lib\site-packages\fastapi\encoders.py", line 137, in jsonable_encoder
    data = dict(obj)
TypeError: 'numpy.int64' object is not iterable

During handling of the above exception, another exception occurred:

Traceback (most recent call last):
  File "C:\Users\PatCa\anaconda3\lib\site-packages\fastapi\encoders.py", line 141, in jsonable_encoder
    data = vars(obj)
TypeError: vars() argument must have __dict__ attribute

During handling of the above exception, another exception occurred:

Traceback (most recent call last):
  File "C:\Users\PatCa\anaconda3\lib\site-packages\uvicorn\protocols\http\h11_impl.py", line 373, in run_asgi
    result = await app(self.scope, self.receive, self.send)
  File "C:\Users\PatCa\anaconda3\lib\site-packages\uvicorn\middleware\proxy_headers.py", line 75, in __call__
    return await self.app(scope, receive, send)
  File "C:\Users\PatCa\anaconda3\lib\site-packages\fastapi\applications.py", line 208, in __call__
    await super().__call__(scope, receive, send)
  File "C:\Users\PatCa\anaconda3\lib\site-packages\starlette\applications.py", line 112, in __call__
    await self.middleware_stack(scope, receive, send)
  File "C:\Users\PatCa\anaconda3\lib\site-packages\starlette\middleware\errors.py", line 181, in __call__
    raise exc
  File "C:\Users\PatCa\anaconda3\lib\site-packages\starlette\middleware\errors.py", line 159, in __call__
    await self.app(scope, receive, _send)
  File "C:\Users\PatCa\anaconda3\lib\site-packages\starlette\exceptions.py", line 82, in __call__
    raise exc
  File "C:\Users\PatCa\anaconda3\lib\site-packages\starlette\exceptions.py", line 71, in __call__
    await self.app(scope, receive, sender)
  File "C:\Users\PatCa\anaconda3\lib\site-packages\starlette\routing.py", line 656, in __call__
    await route.handle(scope, receive, send)
  File "C:\Users\PatCa\anaconda3\lib\site-packages\starlette\routing.py", line 259, in handle
    await self.app(scope, receive, send)
  File "C:\Users\PatCa\anaconda3\lib\site-packages\starlette\routing.py", line 61, in app
    response = await func(request)
  File "C:\Users\PatCa\anaconda3\lib\site-packages\fastapi\routing.py", line 234, in app
    response_data = await serialize_response(
  File "C:\Users\PatCa\anaconda3\lib\site-packages\fastapi\routing.py", line 148, in serialize_response
    return jsonable_encoder(response_content)
  File "C:\Users\PatCa\anaconda3\lib\site-packages\fastapi\encoders.py", line 93, in jsonable_encoder
    encoded_value = jsonable_encoder(
  File "C:\Users\PatCa\anaconda3\lib\site-packages\fastapi\encoders.py", line 145, in jsonable_encoder
    return jsonable_encoder(
  File "C:\Users\PatCa\anaconda3\lib\site-packages\fastapi\encoders.py", line 93, in jsonable_encoder
    encoded_value = jsonable_encoder(
  File "C:\Users\PatCa\anaconda3\lib\site-packages\fastapi\encoders.py", line 144, in jsonable_encoder
    raise ValueError(errors)
ValueError: [TypeError("'numpy.int64' object is not iterable"), TypeError('vars() argument must have __dict__ attribute')]
2022-01-13 17:33:37,839 INFO     Started server process [2400]
2022-01-13 17:33:37,840 INFO     Waiting for application startup.
2022-01-13 17:33:37,841 INFO     Application startup complete.
2022-01-13 17:33:41,597 INFO     Opened feeding page
2022-01-13 17:33:41,788 ERROR    Exception in ASGI application
Traceback (most recent call last):
  File "C:\Users\PatCa\anaconda3\lib\site-packages\uvicorn\protocols\http\h11_impl.py", line 373, in run_asgi
    result = await app(self.scope, self.receive, self.send)
  File "C:\Users\PatCa\anaconda3\lib\site-packages\uvicorn\middleware\proxy_headers.py", line 75, in __call__
    return await self.app(scope, receive, send)
  File "C:\Users\PatCa\anaconda3\lib\site-packages\fastapi\applications.py", line 208, in __call__
    await super().__call__(scope, receive, send)
  File "C:\Users\PatCa\anaconda3\lib\site-packages\starlette\applications.py", line 112, in __call__
    await self.middleware_stack(scope, receive, send)
  File "C:\Users\PatCa\anaconda3\lib\site-packages\starlette\middleware\errors.py", line 181, in __call__
    raise exc
  File "C:\Users\PatCa\anaconda3\lib\site-packages\starlette\middleware\errors.py", line 159, in __call__
    await self.app(scope, receive, _send)
  File "C:\Users\PatCa\anaconda3\lib\site-packages\starlette\exceptions.py", line 82, in __call__
    raise exc
  File "C:\Users\PatCa\anaconda3\lib\site-packages\starlette\exceptions.py", line 71, in __call__
    await self.app(scope, receive, sender)
  File "C:\Users\PatCa\anaconda3\lib\site-packages\starlette\routing.py", line 656, in __call__
    await route.handle(scope, receive, send)
  File "C:\Users\PatCa\anaconda3\lib\site-packages\starlette\routing.py", line 259, in handle
    await self.app(scope, receive, send)
  File "C:\Users\PatCa\anaconda3\lib\site-packages\starlette\routing.py", line 61, in app
    response = await func(request)
  File "C:\Users\PatCa\anaconda3\lib\site-packages\fastapi\routing.py", line 226, in app
    raw_response = await run_endpoint_function(
  File "C:\Users\PatCa\anaconda3\lib\site-packages\fastapi\routing.py", line 161, in run_endpoint_function
    return await run_in_threadpool(dependant.call, **values)
  File "C:\Users\PatCa\anaconda3\lib\site-packages\starlette\concurrency.py", line 39, in run_in_threadpool
    return await anyio.to_thread.run_sync(func, *args)
  File "C:\Users\PatCa\anaconda3\lib\site-packages\anyio\to_thread.py", line 28, in run_sync
    return await get_asynclib().run_sync_in_worker_thread(func, *args, cancellable=cancellable,
  File "C:\Users\PatCa\anaconda3\lib\site-packages\anyio\_backends\_asyncio.py", line 805, in run_sync_in_worker_thread
    return await future
  File "C:\Users\PatCa\anaconda3\lib\site-packages\anyio\_backends\_asyncio.py", line 743, in run
    result = func(*args)
  File ".\app\main.py", line 72, in feeding
    return {q: result2}
NameError: name 'q' is not defined
2022-01-13 17:33:56,404 INFO     Started server process [14788]
2022-01-13 17:33:56,405 INFO     Waiting for application startup.
2022-01-13 17:33:56,406 INFO     Application startup complete.
2022-01-13 17:34:02,518 INFO     Opened feeding page
2022-01-13 17:34:02,733 ERROR    Exception in ASGI application
Traceback (most recent call last):
  File "C:\Users\PatCa\anaconda3\lib\site-packages\fastapi\encoders.py", line 137, in jsonable_encoder
    data = dict(obj)
TypeError: 'numpy.int64' object is not iterable

During handling of the above exception, another exception occurred:

Traceback (most recent call last):
  File "C:\Users\PatCa\anaconda3\lib\site-packages\fastapi\encoders.py", line 141, in jsonable_encoder
    data = vars(obj)
TypeError: vars() argument must have __dict__ attribute

During handling of the above exception, another exception occurred:

Traceback (most recent call last):
  File "C:\Users\PatCa\anaconda3\lib\site-packages\uvicorn\protocols\http\h11_impl.py", line 373, in run_asgi
    result = await app(self.scope, self.receive, self.send)
  File "C:\Users\PatCa\anaconda3\lib\site-packages\uvicorn\middleware\proxy_headers.py", line 75, in __call__
    return await self.app(scope, receive, send)
  File "C:\Users\PatCa\anaconda3\lib\site-packages\fastapi\applications.py", line 208, in __call__
    await super().__call__(scope, receive, send)
  File "C:\Users\PatCa\anaconda3\lib\site-packages\starlette\applications.py", line 112, in __call__
    await self.middleware_stack(scope, receive, send)
  File "C:\Users\PatCa\anaconda3\lib\site-packages\starlette\middleware\errors.py", line 181, in __call__
    raise exc
  File "C:\Users\PatCa\anaconda3\lib\site-packages\starlette\middleware\errors.py", line 159, in __call__
    await self.app(scope, receive, _send)
  File "C:\Users\PatCa\anaconda3\lib\site-packages\starlette\exceptions.py", line 82, in __call__
    raise exc
  File "C:\Users\PatCa\anaconda3\lib\site-packages\starlette\exceptions.py", line 71, in __call__
    await self.app(scope, receive, sender)
  File "C:\Users\PatCa\anaconda3\lib\site-packages\starlette\routing.py", line 656, in __call__
    await route.handle(scope, receive, send)
  File "C:\Users\PatCa\anaconda3\lib\site-packages\starlette\routing.py", line 259, in handle
    await self.app(scope, receive, send)
  File "C:\Users\PatCa\anaconda3\lib\site-packages\starlette\routing.py", line 61, in app
    response = await func(request)
  File "C:\Users\PatCa\anaconda3\lib\site-packages\fastapi\routing.py", line 234, in app
    response_data = await serialize_response(
  File "C:\Users\PatCa\anaconda3\lib\site-packages\fastapi\routing.py", line 148, in serialize_response
    return jsonable_encoder(response_content)
  File "C:\Users\PatCa\anaconda3\lib\site-packages\fastapi\encoders.py", line 93, in jsonable_encoder
    encoded_value = jsonable_encoder(
  File "C:\Users\PatCa\anaconda3\lib\site-packages\fastapi\encoders.py", line 93, in jsonable_encoder
    encoded_value = jsonable_encoder(
  File "C:\Users\PatCa\anaconda3\lib\site-packages\fastapi\encoders.py", line 145, in jsonable_encoder
    return jsonable_encoder(
  File "C:\Users\PatCa\anaconda3\lib\site-packages\fastapi\encoders.py", line 93, in jsonable_encoder
    encoded_value = jsonable_encoder(
  File "C:\Users\PatCa\anaconda3\lib\site-packages\fastapi\encoders.py", line 144, in jsonable_encoder
    raise ValueError(errors)
ValueError: [TypeError("'numpy.int64' object is not iterable"), TypeError('vars() argument must have __dict__ attribute')]
2022-01-13 17:34:14,319 INFO     Started server process [16088]
2022-01-13 17:34:14,320 INFO     Waiting for application startup.
2022-01-13 17:34:14,321 INFO     Application startup complete.
2022-01-13 17:34:16,824 INFO     Opened feeding page
2022-01-13 17:34:17,010 ERROR    Exception in ASGI application
Traceback (most recent call last):
  File "C:\Users\PatCa\anaconda3\lib\site-packages\uvicorn\protocols\http\h11_impl.py", line 373, in run_asgi
    result = await app(self.scope, self.receive, self.send)
  File "C:\Users\PatCa\anaconda3\lib\site-packages\uvicorn\middleware\proxy_headers.py", line 75, in __call__
    return await self.app(scope, receive, send)
  File "C:\Users\PatCa\anaconda3\lib\site-packages\fastapi\applications.py", line 208, in __call__
    await super().__call__(scope, receive, send)
  File "C:\Users\PatCa\anaconda3\lib\site-packages\starlette\applications.py", line 112, in __call__
    await self.middleware_stack(scope, receive, send)
  File "C:\Users\PatCa\anaconda3\lib\site-packages\starlette\middleware\errors.py", line 181, in __call__
    raise exc
  File "C:\Users\PatCa\anaconda3\lib\site-packages\starlette\middleware\errors.py", line 159, in __call__
    await self.app(scope, receive, _send)
  File "C:\Users\PatCa\anaconda3\lib\site-packages\starlette\exceptions.py", line 82, in __call__
    raise exc
  File "C:\Users\PatCa\anaconda3\lib\site-packages\starlette\exceptions.py", line 71, in __call__
    await self.app(scope, receive, sender)
  File "C:\Users\PatCa\anaconda3\lib\site-packages\starlette\routing.py", line 656, in __call__
    await route.handle(scope, receive, send)
  File "C:\Users\PatCa\anaconda3\lib\site-packages\starlette\routing.py", line 259, in handle
    await self.app(scope, receive, send)
  File "C:\Users\PatCa\anaconda3\lib\site-packages\starlette\routing.py", line 61, in app
    response = await func(request)
  File "C:\Users\PatCa\anaconda3\lib\site-packages\fastapi\routing.py", line 226, in app
    raw_response = await run_endpoint_function(
  File "C:\Users\PatCa\anaconda3\lib\site-packages\fastapi\routing.py", line 161, in run_endpoint_function
    return await run_in_threadpool(dependant.call, **values)
  File "C:\Users\PatCa\anaconda3\lib\site-packages\starlette\concurrency.py", line 39, in run_in_threadpool
    return await anyio.to_thread.run_sync(func, *args)
  File "C:\Users\PatCa\anaconda3\lib\site-packages\anyio\to_thread.py", line 28, in run_sync
    return await get_asynclib().run_sync_in_worker_thread(func, *args, cancellable=cancellable,
  File "C:\Users\PatCa\anaconda3\lib\site-packages\anyio\_backends\_asyncio.py", line 805, in run_sync_in_worker_thread
    return await future
  File "C:\Users\PatCa\anaconda3\lib\site-packages\anyio\_backends\_asyncio.py", line 743, in run
    result = func(*args)
  File ".\app\main.py", line 72, in feeding
    return {result2}
TypeError: unhashable type: 'dict'
2022-01-13 17:37:24,473 INFO     Started server process [18000]
2022-01-13 17:37:24,474 INFO     Waiting for application startup.
2022-01-13 17:37:24,474 INFO     Application startup complete.
2022-01-13 17:37:29,820 INFO     Opened feeding page
2022-01-13 17:37:30,029 ERROR    Exception in ASGI application
Traceback (most recent call last):
  File "C:\Users\PatCa\anaconda3\lib\site-packages\uvicorn\protocols\http\h11_impl.py", line 373, in run_asgi
    result = await app(self.scope, self.receive, self.send)
  File "C:\Users\PatCa\anaconda3\lib\site-packages\uvicorn\middleware\proxy_headers.py", line 75, in __call__
    return await self.app(scope, receive, send)
  File "C:\Users\PatCa\anaconda3\lib\site-packages\fastapi\applications.py", line 208, in __call__
    await super().__call__(scope, receive, send)
  File "C:\Users\PatCa\anaconda3\lib\site-packages\starlette\applications.py", line 112, in __call__
    await self.middleware_stack(scope, receive, send)
  File "C:\Users\PatCa\anaconda3\lib\site-packages\starlette\middleware\errors.py", line 181, in __call__
    raise exc
  File "C:\Users\PatCa\anaconda3\lib\site-packages\starlette\middleware\errors.py", line 159, in __call__
    await self.app(scope, receive, _send)
  File "C:\Users\PatCa\anaconda3\lib\site-packages\starlette\exceptions.py", line 82, in __call__
    raise exc
  File "C:\Users\PatCa\anaconda3\lib\site-packages\starlette\exceptions.py", line 71, in __call__
    await self.app(scope, receive, sender)
  File "C:\Users\PatCa\anaconda3\lib\site-packages\starlette\routing.py", line 656, in __call__
    await route.handle(scope, receive, send)
  File "C:\Users\PatCa\anaconda3\lib\site-packages\starlette\routing.py", line 259, in handle
    await self.app(scope, receive, send)
  File "C:\Users\PatCa\anaconda3\lib\site-packages\starlette\routing.py", line 61, in app
    response = await func(request)
  File "C:\Users\PatCa\anaconda3\lib\site-packages\fastapi\routing.py", line 226, in app
    raw_response = await run_endpoint_function(
  File "C:\Users\PatCa\anaconda3\lib\site-packages\fastapi\routing.py", line 161, in run_endpoint_function
    return await run_in_threadpool(dependant.call, **values)
  File "C:\Users\PatCa\anaconda3\lib\site-packages\starlette\concurrency.py", line 39, in run_in_threadpool
    return await anyio.to_thread.run_sync(func, *args)
  File "C:\Users\PatCa\anaconda3\lib\site-packages\anyio\to_thread.py", line 28, in run_sync
    return await get_asynclib().run_sync_in_worker_thread(func, *args, cancellable=cancellable,
  File "C:\Users\PatCa\anaconda3\lib\site-packages\anyio\_backends\_asyncio.py", line 805, in run_sync_in_worker_thread
    return await future
  File "C:\Users\PatCa\anaconda3\lib\site-packages\anyio\_backends\_asyncio.py", line 743, in run
    result = func(*args)
  File ".\app\main.py", line 72, in feeding
    return json.dumps(result2)
  File "C:\Users\PatCa\anaconda3\lib\json\__init__.py", line 231, in dumps
    return _default_encoder.encode(obj)
  File "C:\Users\PatCa\anaconda3\lib\json\encoder.py", line 199, in encode
    chunks = self.iterencode(o, _one_shot=True)
  File "C:\Users\PatCa\anaconda3\lib\json\encoder.py", line 257, in iterencode
    return _iterencode(o, 0)
  File "C:\Users\PatCa\anaconda3\lib\json\encoder.py", line 179, in default
    raise TypeError(f'Object of type {o.__class__.__name__} '
TypeError: Object of type Series is not JSON serializable
2022-01-13 17:38:09,041 INFO     Started server process [18044]
2022-01-13 17:38:09,041 INFO     Waiting for application startup.
2022-01-13 17:38:09,042 INFO     Application startup complete.
2022-01-13 17:38:11,876 INFO     Opened feeding page
2022-01-13 17:38:12,083 ERROR    Exception in ASGI application
Traceback (most recent call last):
  File "C:\Users\PatCa\anaconda3\lib\site-packages\uvicorn\protocols\http\h11_impl.py", line 373, in run_asgi
    result = await app(self.scope, self.receive, self.send)
  File "C:\Users\PatCa\anaconda3\lib\site-packages\uvicorn\middleware\proxy_headers.py", line 75, in __call__
    return await self.app(scope, receive, send)
  File "C:\Users\PatCa\anaconda3\lib\site-packages\fastapi\applications.py", line 208, in __call__
    await super().__call__(scope, receive, send)
  File "C:\Users\PatCa\anaconda3\lib\site-packages\starlette\applications.py", line 112, in __call__
    await self.middleware_stack(scope, receive, send)
  File "C:\Users\PatCa\anaconda3\lib\site-packages\starlette\middleware\errors.py", line 181, in __call__
    raise exc
  File "C:\Users\PatCa\anaconda3\lib\site-packages\starlette\middleware\errors.py", line 159, in __call__
    await self.app(scope, receive, _send)
  File "C:\Users\PatCa\anaconda3\lib\site-packages\starlette\exceptions.py", line 82, in __call__
    raise exc
  File "C:\Users\PatCa\anaconda3\lib\site-packages\starlette\exceptions.py", line 71, in __call__
    await self.app(scope, receive, sender)
  File "C:\Users\PatCa\anaconda3\lib\site-packages\starlette\routing.py", line 656, in __call__
    await route.handle(scope, receive, send)
  File "C:\Users\PatCa\anaconda3\lib\site-packages\starlette\routing.py", line 259, in handle
    await self.app(scope, receive, send)
  File "C:\Users\PatCa\anaconda3\lib\site-packages\starlette\routing.py", line 61, in app
    response = await func(request)
  File "C:\Users\PatCa\anaconda3\lib\site-packages\fastapi\routing.py", line 226, in app
    raw_response = await run_endpoint_function(
  File "C:\Users\PatCa\anaconda3\lib\site-packages\fastapi\routing.py", line 161, in run_endpoint_function
    return await run_in_threadpool(dependant.call, **values)
  File "C:\Users\PatCa\anaconda3\lib\site-packages\starlette\concurrency.py", line 39, in run_in_threadpool
    return await anyio.to_thread.run_sync(func, *args)
  File "C:\Users\PatCa\anaconda3\lib\site-packages\anyio\to_thread.py", line 28, in run_sync
    return await get_asynclib().run_sync_in_worker_thread(func, *args, cancellable=cancellable,
  File "C:\Users\PatCa\anaconda3\lib\site-packages\anyio\_backends\_asyncio.py", line 805, in run_sync_in_worker_thread
    return await future
  File "C:\Users\PatCa\anaconda3\lib\site-packages\anyio\_backends\_asyncio.py", line 743, in run
    result = func(*args)
  File ".\app\main.py", line 72, in feeding
    return json.dumps(result)
  File "C:\Users\PatCa\anaconda3\lib\json\__init__.py", line 231, in dumps
    return _default_encoder.encode(obj)
  File "C:\Users\PatCa\anaconda3\lib\json\encoder.py", line 199, in encode
    chunks = self.iterencode(o, _one_shot=True)
  File "C:\Users\PatCa\anaconda3\lib\json\encoder.py", line 257, in iterencode
    return _iterencode(o, 0)
  File "C:\Users\PatCa\anaconda3\lib\json\encoder.py", line 179, in default
    raise TypeError(f'Object of type {o.__class__.__name__} '
TypeError: Object of type DataFrame is not JSON serializable
2022-01-13 17:39:32,924 INFO     Started server process [16060]
2022-01-13 17:39:32,925 INFO     Waiting for application startup.
2022-01-13 17:39:32,925 INFO     Application startup complete.
2022-01-13 17:39:39,147 INFO     Opened feeding page
2022-01-13 17:39:39,357 ERROR    Exception in ASGI application
Traceback (most recent call last):
  File "C:\Users\PatCa\anaconda3\lib\site-packages\uvicorn\protocols\http\h11_impl.py", line 373, in run_asgi
    result = await app(self.scope, self.receive, self.send)
  File "C:\Users\PatCa\anaconda3\lib\site-packages\uvicorn\middleware\proxy_headers.py", line 75, in __call__
    return await self.app(scope, receive, send)
  File "C:\Users\PatCa\anaconda3\lib\site-packages\fastapi\applications.py", line 208, in __call__
    await super().__call__(scope, receive, send)
  File "C:\Users\PatCa\anaconda3\lib\site-packages\starlette\applications.py", line 112, in __call__
    await self.middleware_stack(scope, receive, send)
  File "C:\Users\PatCa\anaconda3\lib\site-packages\starlette\middleware\errors.py", line 181, in __call__
    raise exc
  File "C:\Users\PatCa\anaconda3\lib\site-packages\starlette\middleware\errors.py", line 159, in __call__
    await self.app(scope, receive, _send)
  File "C:\Users\PatCa\anaconda3\lib\site-packages\starlette\exceptions.py", line 82, in __call__
    raise exc
  File "C:\Users\PatCa\anaconda3\lib\site-packages\starlette\exceptions.py", line 71, in __call__
    await self.app(scope, receive, sender)
  File "C:\Users\PatCa\anaconda3\lib\site-packages\starlette\routing.py", line 656, in __call__
    await route.handle(scope, receive, send)
  File "C:\Users\PatCa\anaconda3\lib\site-packages\starlette\routing.py", line 259, in handle
    await self.app(scope, receive, send)
  File "C:\Users\PatCa\anaconda3\lib\site-packages\starlette\routing.py", line 61, in app
    response = await func(request)
  File "C:\Users\PatCa\anaconda3\lib\site-packages\fastapi\routing.py", line 226, in app
    raw_response = await run_endpoint_function(
  File "C:\Users\PatCa\anaconda3\lib\site-packages\fastapi\routing.py", line 161, in run_endpoint_function
    return await run_in_threadpool(dependant.call, **values)
  File "C:\Users\PatCa\anaconda3\lib\site-packages\starlette\concurrency.py", line 39, in run_in_threadpool
    return await anyio.to_thread.run_sync(func, *args)
  File "C:\Users\PatCa\anaconda3\lib\site-packages\anyio\to_thread.py", line 28, in run_sync
    return await get_asynclib().run_sync_in_worker_thread(func, *args, cancellable=cancellable,
  File "C:\Users\PatCa\anaconda3\lib\site-packages\anyio\_backends\_asyncio.py", line 805, in run_sync_in_worker_thread
    return await future
  File "C:\Users\PatCa\anaconda3\lib\site-packages\anyio\_backends\_asyncio.py", line 743, in run
    result = func(*args)
  File ".\app\main.py", line 71, in feeding
    print(json.dumps(result))
  File "C:\Users\PatCa\anaconda3\lib\json\__init__.py", line 231, in dumps
    return _default_encoder.encode(obj)
  File "C:\Users\PatCa\anaconda3\lib\json\encoder.py", line 199, in encode
    chunks = self.iterencode(o, _one_shot=True)
  File "C:\Users\PatCa\anaconda3\lib\json\encoder.py", line 257, in iterencode
    return _iterencode(o, 0)
  File "C:\Users\PatCa\anaconda3\lib\json\encoder.py", line 179, in default
    raise TypeError(f'Object of type {o.__class__.__name__} '
TypeError: Object of type DataFrame is not JSON serializable
2022-01-13 17:40:05,935 INFO     Started server process [17568]
2022-01-13 17:40:05,936 INFO     Waiting for application startup.
2022-01-13 17:40:05,937 INFO     Application startup complete.
2022-01-13 17:40:33,494 INFO     Opened feeding page
2022-01-13 17:55:11,165 INFO     Started server process [17528]
2022-01-13 17:55:11,166 INFO     Waiting for application startup.
2022-01-13 17:55:11,167 INFO     Application startup complete.
2022-01-13 17:55:37,456 INFO     Started server process [14124]
2022-01-13 17:55:37,457 INFO     Waiting for application startup.
2022-01-13 17:55:37,458 INFO     Application startup complete.
2022-01-13 17:55:40,561 INFO     Opened feeding page
2022-01-13 17:55:51,457 INFO     Opened feeding page
2022-01-13 18:04:32,509 INFO     Started server process [12004]
2022-01-13 18:04:32,510 INFO     Waiting for application startup.
2022-01-13 18:04:32,511 INFO     Application startup complete.
2022-01-13 18:05:56,431 INFO     Opened feeding page
2022-01-13 18:07:49,583 INFO     Opened feeding page
2022-01-13 18:09:08,456 INFO     Opened feeding page
2022-01-13 18:09:31,273 INFO     Opened feeding page
2022-01-13 18:10:47,711 INFO     Opened feeding page
2022-01-13 18:11:24,030 INFO     Opened feeding page
2022-01-13 18:12:27,920 INFO     Opened feeding page
2022-01-13 18:13:14,959 INFO     Opened feeding page
2022-01-13 18:16:50,621 INFO     Opened feeding page
2022-01-13 18:17:41,974 INFO     Opened feeding page
2022-01-13 18:20:23,250 INFO     Opened feeding page
2022-01-13 18:22:02,110 INFO     Opened feeding page
2022-01-13 18:30:34,579 INFO     Opened feeding page
2022-01-14 10:47:47,290 INFO     Started server process [19820]
2022-01-14 10:47:47,291 INFO     Waiting for application startup.
2022-01-14 10:47:47,291 INFO     Application startup complete.
2022-01-14 10:50:09,226 INFO     Opened head circumference page
2022-01-14 10:50:52,127 INFO     Started server process [14512]
2022-01-14 10:50:52,127 INFO     Waiting for application startup.
2022-01-14 10:50:52,128 INFO     Application startup complete.
2022-01-14 10:50:54,272 INFO     Opened head circumference page
2022-01-14 10:51:15,899 INFO     Started server process [10944]
2022-01-14 10:51:15,906 INFO     Waiting for application startup.
2022-01-14 10:51:15,907 INFO     Application startup complete.
2022-01-14 10:51:30,432 INFO     Started server process [18120]
2022-01-14 10:51:30,432 INFO     Waiting for application startup.
2022-01-14 10:51:30,439 INFO     Application startup complete.
2022-01-14 10:51:56,602 INFO     Started server process [21332]
2022-01-14 10:51:56,603 INFO     Waiting for application startup.
2022-01-14 10:51:56,604 INFO     Application startup complete.
2022-01-14 10:53:42,119 INFO     Opened weight page
2022-01-14 10:57:54,037 INFO     Opened weight page
2022-01-14 10:58:22,913 INFO     Opened weight page
2022-01-14 10:58:32,076 INFO     Opened weight page
2022-01-14 10:58:32,260 INFO     Opened height page
2022-01-14 10:58:32,434 INFO     Opened head circumference page
2022-01-14 11:03:33,011 INFO     Started server process [22136]
2022-01-14 11:03:33,012 INFO     Waiting for application startup.
2022-01-14 11:03:33,014 INFO     Application startup complete.
2022-01-14 11:04:24,657 INFO     Started server process [19152]
2022-01-14 11:04:24,658 INFO     Waiting for application startup.
2022-01-14 11:04:24,659 INFO     Application startup complete.
2022-01-14 11:04:37,823 INFO     Started server process [11244]
2022-01-14 11:04:37,823 INFO     Waiting for application startup.
2022-01-14 11:04:37,825 INFO     Application startup complete.
2022-01-14 11:05:11,800 INFO     Opened weight page
2022-01-14 11:07:30,570 INFO     Opened weight page
2022-01-14 11:07:30,790 INFO     Opened height page
2022-01-14 11:07:30,949 INFO     Opened head circumference page
2022-01-14 11:08:39,155 INFO     Opened weight page
2022-01-14 11:08:39,370 INFO     Opened height page
2022-01-14 11:08:39,532 INFO     Opened head circumference page
2022-01-14 11:10:58,242 INFO     Opened feeding page
2022-01-14 11:10:58,414 INFO     Opened weight page
2022-01-14 11:11:57,646 INFO     Opened feeding page
2022-01-14 11:11:57,829 INFO     Opened weight page
2022-01-14 11:33:54,519 INFO     Opened feeding page
2022-01-14 11:33:54,744 INFO     Opened weight page
2022-01-14 11:34:46,636 INFO     Opened feeding page
2022-01-14 11:34:46,859 INFO     Opened weight page
2022-01-14 13:15:29,998 INFO     Opened feeding page
2022-01-14 13:15:30,218 INFO     Opened weight page
2022-01-14 13:15:52,194 INFO     Opened weight page
2022-01-14 13:15:52,425 INFO     Opened height page
2022-01-14 13:15:52,596 INFO     Opened head circumference page
2022-01-14 13:15:52,937 INFO     Opened feeding page
2022-01-14 13:17:23,434 INFO     Opened weight page
2022-01-14 13:17:23,622 INFO     Opened height page
2022-01-14 13:17:23,779 INFO     Opened head circumference page
2022-01-14 13:17:24,128 INFO     Opened feeding page
2022-01-14 13:18:01,896 INFO     Opened weight page
2022-01-14 13:18:02,116 INFO     Opened height page
2022-01-14 13:18:02,277 INFO     Opened head circumference page
2022-01-14 13:18:02,591 INFO     Opened feeding page
2022-01-14 13:18:23,513 INFO     Opened weight page
2022-01-14 13:18:23,732 INFO     Opened height page
2022-01-14 13:18:23,916 INFO     Opened head circumference page
2022-01-14 13:18:24,286 INFO     Opened feeding page
2022-01-14 13:18:55,493 INFO     Opened weight page
2022-01-14 13:18:55,703 INFO     Opened height page
2022-01-14 13:18:55,877 INFO     Opened head circumference page
2022-01-14 13:18:56,192 INFO     Opened feeding page
2022-01-14 13:19:34,463 INFO     Opened weight page
2022-01-14 13:19:34,687 INFO     Opened height page
2022-01-14 13:19:34,867 INFO     Opened head circumference page
2022-01-14 13:19:35,198 INFO     Opened feeding page
2022-01-14 13:20:18,402 INFO     Opened weight page
2022-01-14 13:20:18,619 INFO     Opened height page
2022-01-14 13:20:18,778 INFO     Opened head circumference page
2022-01-14 13:20:19,107 INFO     Opened feeding page
2022-01-14 13:21:00,875 INFO     Opened weight page
2022-01-14 13:21:01,095 INFO     Opened height page
2022-01-14 13:21:01,264 INFO     Opened head circumference page
2022-01-14 13:21:01,579 INFO     Opened feeding page
2022-01-14 13:21:40,079 INFO     Opened weight page
2022-01-14 13:21:40,300 INFO     Opened height page
2022-01-14 13:21:40,481 INFO     Opened head circumference page
2022-01-14 13:21:40,810 INFO     Opened feeding page
2022-01-14 13:21:58,224 INFO     Opened weight page
2022-01-14 13:21:58,441 INFO     Opened height page
2022-01-14 13:21:58,601 INFO     Opened head circumference page
2022-01-14 13:21:58,933 INFO     Opened feeding page
2022-01-14 13:22:16,849 INFO     Opened weight page
2022-01-14 13:22:17,058 INFO     Opened height page
2022-01-14 13:22:17,221 INFO     Opened head circumference page
2022-01-14 13:22:17,532 INFO     Opened feeding page
2022-01-14 13:30:03,702 INFO     Opened weight page
2022-01-14 13:30:03,927 INFO     Opened height page
2022-01-14 13:30:04,108 INFO     Opened head circumference page
2022-01-14 13:30:04,423 INFO     Opened feeding page
2022-01-14 13:30:31,620 INFO     Opened weight page
2022-01-14 13:30:31,831 INFO     Opened height page
2022-01-14 13:30:31,994 INFO     Opened head circumference page
2022-01-14 13:30:32,309 INFO     Opened feeding page
2022-01-14 13:31:16,312 INFO     Opened weight page
2022-01-14 13:31:16,553 INFO     Opened height page
2022-01-14 13:31:16,726 INFO     Opened head circumference page
2022-01-14 13:31:17,058 INFO     Opened feeding page
2022-01-14 13:44:11,367 INFO     Shutting down
2022-01-14 13:44:11,474 INFO     Waiting for application shutdown.
2022-01-14 13:44:11,474 INFO     Application shutdown complete.
2022-01-14 13:44:11,476 INFO     Finished server process [11244]
